Watching for file changes with StatReloader
[03/Feb/2020 05:13:01] "GET /uper/main_page/ HTTP/1.1" 200 2883
[03/Feb/2020 05:13:05] "GET /uper/driver_register/ HTTP/1.1" 200 40
/home/ubuntu/ece568/erss-hwk1-bh214/docker-deploy/web-app/uper/views.py changed, reloading.
Performing system checks...

System check identified no issues (0 silenced).
February 03, 2020 - 05:12:46
Django version 3.0.2, using settings 'mysite.settings'
Starting development server at http://0:8000/
Quit the server with CONTROL-C.
Watching for file changes with StatReloader
[03/Feb/2020 05:16:58] "GET /uper/main_page/ HTTP/1.1" 200 2883
[03/Feb/2020 05:17:05] "GET /uper/request_ride/ HTTP/1.1" 200 2799
[03/Feb/2020 05:17:20] "GET /uper/view_info/ HTTP/1.1" 200 299
[03/Feb/2020 05:17:46] "GET /uper/edit_driver/ HTTP/1.1" 200 725
[03/Feb/2020 05:17:55] "GET /uper/edit_driver/ HTTP/1.1" 200 725
/usr/local/lib/python3.6/dist-packages/django/db/models/fields/__init__.py:1364: RuntimeWarning: DateTimeField Personal_ride.called_time received a naive datetime (2020-02-03 05:18:00.510871) while time zone support is active.
  RuntimeWarning)
/usr/local/lib/python3.6/dist-packages/django/db/models/fields/__init__.py:1364: RuntimeWarning: DateTimeField Ride.arrival_datetime received a naive datetime (2020-02-10 00:12:00) while time zone support is active.
  RuntimeWarning)
[03/Feb/2020 05:18:00] "POST /uper/request_or_edit_ride_process/ HTTP/1.1" 302 0
[03/Feb/2020 05:18:00] "GET /uper/main_page/ HTTP/1.1" 200 4564
[03/Feb/2020 05:18:26] "POST /uper/edit_driver_process/ HTTP/1.1" 302 0
[03/Feb/2020 05:18:27] "GET /uper/main_page/ HTTP/1.1" 200 2883
[03/Feb/2020 05:18:28] "GET /uper/driver_ride_search/ HTTP/1.1" 200 17
[03/Feb/2020 05:18:42] "GET /uper/driver_ride_search/ HTTP/1.1" 200 17
[03/Feb/2020 05:18:45] "POST /uper/edit_ride/ HTTP/1.1" 200 2009
[03/Feb/2020 05:18:49] "GET /uper/driver_ride_search/ HTTP/1.1" 200 17
[03/Feb/2020 05:18:49] "POST /uper/request_or_edit_ride_process/ HTTP/1.1" 302 0
[03/Feb/2020 05:18:49] "GET /uper/main_page/ HTTP/1.1" 200 4564
[03/Feb/2020 05:18:50] "GET /uper/driver_ride_search/ HTTP/1.1" 200 17
[03/Feb/2020 05:18:52] "GET /uper/driver_ride_search/ HTTP/1.1" 200 17
[03/Feb/2020 05:18:53] "GET /uper/driver_ride_search/ HTTP/1.1" 200 17
[03/Feb/2020 05:18:58] "GET /uper/edit_driver/ HTTP/1.1" 200 725
[03/Feb/2020 05:19:00] "POST /uper/edit_ride/ HTTP/1.1" 200 2009
[03/Feb/2020 05:19:07] "POST /uper/request_or_edit_ride_process/ HTTP/1.1" 302 0
[03/Feb/2020 05:19:07] "GET /uper/main_page/ HTTP/1.1" 200 4567
[03/Feb/2020 05:19:09] "POST /uper/edit_driver_process/ HTTP/1.1" 302 0
[03/Feb/2020 05:19:10] "GET /uper/main_page/ HTTP/1.1" 200 2883
[03/Feb/2020 05:19:11] "GET /uper/driver_ride_search/ HTTP/1.1" 200 17
[03/Feb/2020 05:19:12] "GET /uper/driver_ride_search/ HTTP/1.1" 200 17
[03/Feb/2020 05:19:13] "GET /uper/driver_ride_search/ HTTP/1.1" 200 17
[03/Feb/2020 05:19:15] "GET /uper/driver_ride_search/ HTTP/1.1" 200 17
[03/Feb/2020 05:19:18] "GET /uper/driver_ride_search/ HTTP/1.1" 200 17
[03/Feb/2020 05:19:22] "GET /uper/view_info/ HTTP/1.1" 200 298
[03/Feb/2020 05:19:32] "GET /uper/edit_driver/ HTTP/1.1" 200 725
[03/Feb/2020 05:19:36] "POST /uper/edit_driver_process/ HTTP/1.1" 302 0
[03/Feb/2020 05:19:36] "GET /uper/main_page/ HTTP/1.1" 200 2883
[03/Feb/2020 05:19:42] "GET /uper/view_info/ HTTP/1.1" 200 298
[03/Feb/2020 05:19:54] "GET /uper/edit_driver/ HTTP/1.1" 200 725
[03/Feb/2020 05:19:57] "POST /uper/edit_driver_process/ HTTP/1.1" 302 0
[03/Feb/2020 05:19:57] "GET /uper/main_page/ HTTP/1.1" 200 2883
[03/Feb/2020 05:19:58] "GET /uper/edit_driver/ HTTP/1.1" 200 725
[03/Feb/2020 05:20:00] "GET /uper/view_info/ HTTP/1.1" 200 289
[03/Feb/2020 05:20:03] "GET /uper/driver_ride_search/ HTTP/1.1" 200 17
[03/Feb/2020 05:20:10] "POST /uper/edit_ride/ HTTP/1.1" 200 2012
[03/Feb/2020 05:20:14] "POST /uper/request_or_edit_ride_process/ HTTP/1.1" 302 0
[03/Feb/2020 05:20:14] "GET /uper/main_page/ HTTP/1.1" 200 4568
[03/Feb/2020 05:20:16] "GET /uper/driver_ride_search/ HTTP/1.1" 200 651
Internal Server Error: /uper/take_order/
Traceback (most recent call last):
  File "/usr/local/lib/python3.6/dist-packages/django/core/handlers/exception.py", line 34, in inner
    response = get_response(request)
  File "/usr/local/lib/python3.6/dist-packages/django/core/handlers/base.py", line 115, in _get_response
    response = self.process_exception_by_middleware(e, request)
  File "/usr/local/lib/python3.6/dist-packages/django/core/handlers/base.py", line 113, in _get_response
    response = wrapped_callback(request, *callback_args, **callback_kwargs)
  File "/home/ubuntu/ece568/erss-hwk1-bh214/docker-deploy/web-app/uper/views.py", line 332, in take_order
    user.personal_ride.create(ride = ride,
AttributeError: 'User' object has no attribute 'personal_ride'
[03/Feb/2020 05:20:18] "POST /uper/take_order/ HTTP/1.1" 500 66237
/home/ubuntu/ece568/erss-hwk1-bh214/docker-deploy/web-app/uper/views.py changed, reloading.
Performing system checks...

System check identified no issues (0 silenced).
February 03, 2020 - 05:16:55
Django version 3.0.2, using settings 'mysite.settings'
Starting development server at http://0:8000/
Quit the server with CONTROL-C.
Watching for file changes with StatReloader
Internal Server Error: /uper/take_order/
Traceback (most recent call last):
  File "/usr/local/lib/python3.6/dist-packages/django/db/backends/utils.py", line 86, in _execute
    return self.cursor.execute(sql, params)
psycopg2.errors.NotNullViolation: null value in column "called_time" violates not-null constraint
DETAIL:  Failing row contains (24, null, driver, 0, 12, 18).


The above exception was the direct cause of the following exception:

Traceback (most recent call last):
  File "/usr/local/lib/python3.6/dist-packages/django/core/handlers/exception.py", line 34, in inner
    response = get_response(request)
  File "/usr/local/lib/python3.6/dist-packages/django/core/handlers/base.py", line 115, in _get_response
    response = self.process_exception_by_middleware(e, request)
  File "/usr/local/lib/python3.6/dist-packages/django/core/handlers/base.py", line 113, in _get_response
    response = wrapped_callback(request, *callback_args, **callback_kwargs)
  File "/home/ubuntu/ece568/erss-hwk1-bh214/docker-deploy/web-app/uper/views.py", line 334, in take_order
    party_person_number = 0,
  File "/usr/local/lib/python3.6/dist-packages/django/db/models/fields/related_descriptors.py", line 676, in create
    return super(RelatedManager, self.db_manager(db)).create(**kwargs)
  File "/usr/local/lib/python3.6/dist-packages/django/db/models/manager.py", line 82, in manager_method
    return getattr(self.get_queryset(), name)(*args, **kwargs)
  File "/usr/local/lib/python3.6/dist-packages/django/db/models/query.py", line 433, in create
    obj.save(force_insert=True, using=self.db)
  File "/usr/local/lib/python3.6/dist-packages/django/db/models/base.py", line 746, in save
    force_update=force_update, update_fields=update_fields)
  File "/usr/local/lib/python3.6/dist-packages/django/db/models/base.py", line 784, in save_base
    force_update, using, update_fields,
  File "/usr/local/lib/python3.6/dist-packages/django/db/models/base.py", line 887, in _save_table
    results = self._do_insert(cls._base_manager, using, fields, returning_fields, raw)
  File "/usr/local/lib/python3.6/dist-packages/django/db/models/base.py", line 926, in _do_insert
    using=using, raw=raw,
  File "/usr/local/lib/python3.6/dist-packages/django/db/models/manager.py", line 82, in manager_method
    return getattr(self.get_queryset(), name)(*args, **kwargs)
  File "/usr/local/lib/python3.6/dist-packages/django/db/models/query.py", line 1204, in _insert
    return query.get_compiler(using=using).execute_sql(returning_fields)
  File "/usr/local/lib/python3.6/dist-packages/django/db/models/sql/compiler.py", line 1384, in execute_sql
    cursor.execute(sql, params)
  File "/usr/local/lib/python3.6/dist-packages/django/db/backends/utils.py", line 100, in execute
    return super().execute(sql, params)
  File "/usr/local/lib/python3.6/dist-packages/django/db/backends/utils.py", line 68, in execute
    return self._execute_with_wrappers(sql, params, many=False, executor=self._execute)
  File "/usr/local/lib/python3.6/dist-packages/django/db/backends/utils.py", line 77, in _execute_with_wrappers
    return executor(sql, params, many, context)
  File "/usr/local/lib/python3.6/dist-packages/django/db/backends/utils.py", line 86, in _execute
    return self.cursor.execute(sql, params)
  File "/usr/local/lib/python3.6/dist-packages/django/db/utils.py", line 90, in __exit__
    raise dj_exc_value.with_traceback(traceback) from exc_value
  File "/usr/local/lib/python3.6/dist-packages/django/db/backends/utils.py", line 86, in _execute
    return self.cursor.execute(sql, params)
django.db.utils.IntegrityError: null value in column "called_time" violates not-null constraint
DETAIL:  Failing row contains (24, null, driver, 0, 12, 18).

[03/Feb/2020 05:21:12] "POST /uper/take_order/ HTTP/1.1" 500 153463
[03/Feb/2020 05:21:21] "GET /uper/driver_ride_search/ HTTP/1.1" 200 651
Internal Server Error: /uper/take_order/
Traceback (most recent call last):
  File "/usr/local/lib/python3.6/dist-packages/django/db/backends/utils.py", line 86, in _execute
    return self.cursor.execute(sql, params)
psycopg2.errors.NotNullViolation: null value in column "called_time" violates not-null constraint
DETAIL:  Failing row contains (25, null, driver, 0, 12, 18).


The above exception was the direct cause of the following exception:

Traceback (most recent call last):
  File "/usr/local/lib/python3.6/dist-packages/django/core/handlers/exception.py", line 34, in inner
    response = get_response(request)
  File "/usr/local/lib/python3.6/dist-packages/django/core/handlers/base.py", line 115, in _get_response
    response = self.process_exception_by_middleware(e, request)
  File "/usr/local/lib/python3.6/dist-packages/django/core/handlers/base.py", line 113, in _get_response
    response = wrapped_callback(request, *callback_args, **callback_kwargs)
  File "/home/ubuntu/ece568/erss-hwk1-bh214/docker-deploy/web-app/uper/views.py", line 334, in take_order
    party_person_number = 0,
  File "/usr/local/lib/python3.6/dist-packages/django/db/models/fields/related_descriptors.py", line 676, in create
    return super(RelatedManager, self.db_manager(db)).create(**kwargs)
  File "/usr/local/lib/python3.6/dist-packages/django/db/models/manager.py", line 82, in manager_method
    return getattr(self.get_queryset(), name)(*args, **kwargs)
  File "/usr/local/lib/python3.6/dist-packages/django/db/models/query.py", line 433, in create
    obj.save(force_insert=True, using=self.db)
  File "/usr/local/lib/python3.6/dist-packages/django/db/models/base.py", line 746, in save
    force_update=force_update, update_fields=update_fields)
  File "/usr/local/lib/python3.6/dist-packages/django/db/models/base.py", line 784, in save_base
    force_update, using, update_fields,
  File "/usr/local/lib/python3.6/dist-packages/django/db/models/base.py", line 887, in _save_table
    results = self._do_insert(cls._base_manager, using, fields, returning_fields, raw)
  File "/usr/local/lib/python3.6/dist-packages/django/db/models/base.py", line 926, in _do_insert
    using=using, raw=raw,
  File "/usr/local/lib/python3.6/dist-packages/django/db/models/manager.py", line 82, in manager_method
    return getattr(self.get_queryset(), name)(*args, **kwargs)
  File "/usr/local/lib/python3.6/dist-packages/django/db/models/query.py", line 1204, in _insert
    return query.get_compiler(using=using).execute_sql(returning_fields)
  File "/usr/local/lib/python3.6/dist-packages/django/db/models/sql/compiler.py", line 1384, in execute_sql
    cursor.execute(sql, params)
  File "/usr/local/lib/python3.6/dist-packages/django/db/backends/utils.py", line 100, in execute
    return super().execute(sql, params)
  File "/usr/local/lib/python3.6/dist-packages/django/db/backends/utils.py", line 68, in execute
    return self._execute_with_wrappers(sql, params, many=False, executor=self._execute)
  File "/usr/local/lib/python3.6/dist-packages/django/db/backends/utils.py", line 77, in _execute_with_wrappers
    return executor(sql, params, many, context)
  File "/usr/local/lib/python3.6/dist-packages/django/db/backends/utils.py", line 86, in _execute
    return self.cursor.execute(sql, params)
  File "/usr/local/lib/python3.6/dist-packages/django/db/utils.py", line 90, in __exit__
    raise dj_exc_value.with_traceback(traceback) from exc_value
  File "/usr/local/lib/python3.6/dist-packages/django/db/backends/utils.py", line 86, in _execute
    return self.cursor.execute(sql, params)
django.db.utils.IntegrityError: null value in column "called_time" violates not-null constraint
DETAIL:  Failing row contains (25, null, driver, 0, 12, 18).

[03/Feb/2020 05:21:22] "POST /uper/take_order/ HTTP/1.1" 500 153463
/home/ubuntu/ece568/erss-hwk1-bh214/docker-deploy/web-app/uper/views.py changed, reloading.
Performing system checks...

System check identified no issues (0 silenced).
February 03, 2020 - 05:21:05
Django version 3.0.2, using settings 'mysite.settings'
Starting development server at http://0:8000/
Quit the server with CONTROL-C.
Watching for file changes with StatReloader
Internal Server Error: /uper/take_order/
Traceback (most recent call last):
  File "/usr/local/lib/python3.6/dist-packages/django/core/handlers/exception.py", line 34, in inner
    response = get_response(request)
  File "/usr/local/lib/python3.6/dist-packages/django/core/handlers/base.py", line 115, in _get_response
    response = self.process_exception_by_middleware(e, request)
  File "/usr/local/lib/python3.6/dist-packages/django/core/handlers/base.py", line 113, in _get_response
    response = wrapped_callback(request, *callback_args, **callback_kwargs)
  File "/home/ubuntu/ece568/erss-hwk1-bh214/docker-deploy/web-app/uper/views.py", line 334, in take_order
    called_time = datetime.now(),
AttributeError: module 'datetime' has no attribute 'now'
[03/Feb/2020 05:22:29] "POST /uper/take_order/ HTTP/1.1" 500 66263
/home/ubuntu/ece568/erss-hwk1-bh214/docker-deploy/web-app/uper/views.py changed, reloading.
Performing system checks...

System check identified no issues (0 silenced).
February 03, 2020 - 05:22:24
Django version 3.0.2, using settings 'mysite.settings'
Starting development server at http://0:8000/
Quit the server with CONTROL-C.
Watching for file changes with StatReloader
/usr/local/lib/python3.6/dist-packages/django/db/models/fields/__init__.py:1364: RuntimeWarning: DateTimeField Personal_ride.called_time received a naive datetime (2020-02-03 05:22:59.307629) while time zone support is active.
  RuntimeWarning)
[03/Feb/2020 05:22:59] "POST /uper/take_order/ HTTP/1.1" 302 0
[03/Feb/2020 05:22:59] "GET /uper/main_page/ HTTP/1.1" 200 2883
[03/Feb/2020 05:23:04] "GET /uper/driver_ride_search/ HTTP/1.1" 200 17
[03/Feb/2020 05:23:22] "GET /uper/main_page/ HTTP/1.1" 200 4345
/home/ubuntu/ece568/erss-hwk1-bh214/docker-deploy/web-app/uper/views.py changed, reloading.
Performing system checks...

System check identified no issues (0 silenced).
February 03, 2020 - 05:22:55
Django version 3.0.2, using settings 'mysite.settings'
Starting development server at http://0:8000/
Quit the server with CONTROL-C.
Watching for file changes with StatReloader
[03/Feb/2020 05:28:37] "GET /uper/request_ride/ HTTP/1.1" 200 2799
/usr/local/lib/python3.6/dist-packages/django/db/models/fields/__init__.py:1364: RuntimeWarning: DateTimeField Personal_ride.called_time received a naive datetime (2020-02-03 05:29:02.526898) while time zone support is active.
  RuntimeWarning)
/usr/local/lib/python3.6/dist-packages/django/db/models/fields/__init__.py:1364: RuntimeWarning: DateTimeField Ride.arrival_datetime received a naive datetime (1211-12-31 02:12:00) while time zone support is active.
  RuntimeWarning)
[03/Feb/2020 05:29:02] "POST /uper/request_or_edit_ride_process/ HTTP/1.1" 302 0
[03/Feb/2020 05:29:02] "GET /uper/main_page/ HTTP/1.1" 200 3837
[03/Feb/2020 05:29:10] "GET /uper/share_ride_search/ HTTP/1.1" 200 663
/usr/local/lib/python3.6/dist-packages/django/db/models/fields/__init__.py:1364: RuntimeWarning: DateTimeField Ride.arrival_datetime received a naive datetime (1211-12-31 02:11:00) while time zone support is active.
  RuntimeWarning)
/usr/local/lib/python3.6/dist-packages/django/db/models/fields/__init__.py:1364: RuntimeWarning: DateTimeField Ride.arrival_datetime received a naive datetime (1211-12-31 02:10:00) while time zone support is active.
  RuntimeWarning)
[03/Feb/2020 05:30:02] "POST /uper/shareride_search_result/ HTTP/1.1" 200 16
/usr/local/lib/python3.6/dist-packages/django/db/models/fields/__init__.py:1364: RuntimeWarning: DateTimeField Ride.arrival_datetime received a naive datetime (1211-12-31 02:13:00) while time zone support is active.
  RuntimeWarning)
[03/Feb/2020 05:30:06] "POST /uper/shareride_search_result/ HTTP/1.1" 200 766
[03/Feb/2020 05:30:09] "POST /uper/join_shareride/ HTTP/1.1" 302 0
[03/Feb/2020 05:30:09] "GET /uper/main_page/ HTTP/1.1" 200 4345
[03/Feb/2020 05:30:14] "GET /uper/main_page/ HTTP/1.1" 200 3837
[03/Feb/2020 12:42:37] code 400, message Bad request version ('À\x14À')
[03/Feb/2020 12:42:37] You're accessing the development server over HTTPS, but it only supports HTTP.

Not Found: /
[03/Feb/2020 13:51:09] "GET / HTTP/1.1" 404 2031
----------------------------------------
Exception happened during processing of request from ('185.184.79.32', 60000)
Traceback (most recent call last):
  File "/usr/lib/python3.6/socketserver.py", line 654, in process_request_thread
    self.finish_request(request, client_address)
  File "/usr/lib/python3.6/socketserver.py", line 364, in finish_request
    self.RequestHandlerClass(request, client_address, self)
  File "/usr/lib/python3.6/socketserver.py", line 724, in __init__
    self.handle()
  File "/usr/local/lib/python3.6/dist-packages/django/core/servers/basehttp.py", line 172, in handle
    self.handle_one_request()
  File "/usr/local/lib/python3.6/dist-packages/django/core/servers/basehttp.py", line 182, in handle_one_request
    self.raw_requestline = self.rfile.readline(65537)
  File "/usr/lib/python3.6/socket.py", line 586, in readinto
    return self._sock.recv_into(b)
ConnectionResetError: [Errno 104] Connection reset by peer
----------------------------------------
Not Found: /ip.ws.126.net:443
[04/Feb/2020 02:19:17] "CONNECT ip.ws.126.net:443 HTTP/1.1" 404 1670
Not Found: /
[04/Feb/2020 14:45:23] "GET / HTTP/1.1" 404 2032
Not Found: /ip.ws.126.net:443
[04/Feb/2020 20:23:19] "CONNECT ip.ws.126.net:443 HTTP/1.1" 404 1670
----------------------------------------
Exception happened during processing of request from ('222.186.19.221', 55548)
Traceback (most recent call last):
  File "/usr/lib/python3.6/socketserver.py", line 654, in process_request_thread
    self.finish_request(request, client_address)
  File "/usr/lib/python3.6/socketserver.py", line 364, in finish_request
    self.RequestHandlerClass(request, client_address, self)
  File "/usr/lib/python3.6/socketserver.py", line 724, in __init__
    self.handle()
  File "/usr/local/lib/python3.6/dist-packages/django/core/servers/basehttp.py", line 174, in handle
    self.handle_one_request()
  File "/usr/local/lib/python3.6/dist-packages/django/core/servers/basehttp.py", line 182, in handle_one_request
    self.raw_requestline = self.rfile.readline(65537)
  File "/usr/lib/python3.6/socket.py", line 586, in readinto
    return self._sock.recv_into(b)
ConnectionResetError: [Errno 104] Connection reset by peer
----------------------------------------
Not Found: /
[05/Feb/2020 00:20:28] "GET / HTTP/1.1" 404 2031
Not Found: /
[05/Feb/2020 06:01:05] "GET / HTTP/1.1" 404 2031
----------------------------------------
Exception happened during processing of request from ('198.108.67.48', 45366)
Traceback (most recent call last):
  File "/usr/lib/python3.6/socketserver.py", line 654, in process_request_thread
    self.finish_request(request, client_address)
  File "/usr/lib/python3.6/socketserver.py", line 364, in finish_request
    self.RequestHandlerClass(request, client_address, self)
  File "/usr/lib/python3.6/socketserver.py", line 724, in __init__
    self.handle()
  File "/usr/local/lib/python3.6/dist-packages/django/core/servers/basehttp.py", line 174, in handle
    self.handle_one_request()
  File "/usr/local/lib/python3.6/dist-packages/django/core/servers/basehttp.py", line 182, in handle_one_request
    self.raw_requestline = self.rfile.readline(65537)
  File "/usr/lib/python3.6/socket.py", line 586, in readinto
    return self._sock.recv_into(b)
ConnectionResetError: [Errno 104] Connection reset by peer
----------------------------------------
----------------------------------------
Exception happened during processing of request from ('185.151.242.90', 60000)
Traceback (most recent call last):
  File "/usr/lib/python3.6/socketserver.py", line 654, in process_request_thread
    self.finish_request(request, client_address)
  File "/usr/lib/python3.6/socketserver.py", line 364, in finish_request
    self.RequestHandlerClass(request, client_address, self)
  File "/usr/lib/python3.6/socketserver.py", line 724, in __init__
    self.handle()
  File "/usr/local/lib/python3.6/dist-packages/django/core/servers/basehttp.py", line 172, in handle
    self.handle_one_request()
  File "/usr/local/lib/python3.6/dist-packages/django/core/servers/basehttp.py", line 182, in handle_one_request
    self.raw_requestline = self.rfile.readline(65537)
  File "/usr/lib/python3.6/socket.py", line 586, in readinto
    return self._sock.recv_into(b)
ConnectionResetError: [Errno 104] Connection reset by peer
----------------------------------------
[05/Feb/2020 16:11:05] code 400, message Bad request syntax ('\x16\x03\x01\x00u\x01\x00\x00q\x03\x03$#j\x97\x15RC\tã\x03ì\\Ú\xa0³Ò¯\x99ü\x1a\x85n\x8ab¤Î\x14\x01E÷PL\x00\x00\x1aÀ/À+À\x11À\x07À\x13À\tÀ\x14À')
[05/Feb/2020 16:11:05] You're accessing the development server over HTTPS, but it only supports HTTP.

----------------------------------------
Exception happened during processing of request from ('185.156.177.224', 20548)
Traceback (most recent call last):
  File "/usr/lib/python3.6/socketserver.py", line 654, in process_request_thread
    self.finish_request(request, client_address)
  File "/usr/lib/python3.6/socketserver.py", line 364, in finish_request
    self.RequestHandlerClass(request, client_address, self)
  File "/usr/lib/python3.6/socketserver.py", line 724, in __init__
    self.handle()
  File "/usr/local/lib/python3.6/dist-packages/django/core/servers/basehttp.py", line 172, in handle
    self.handle_one_request()
  File "/usr/local/lib/python3.6/dist-packages/django/core/servers/basehttp.py", line 182, in handle_one_request
    self.raw_requestline = self.rfile.readline(65537)
  File "/usr/lib/python3.6/socket.py", line 586, in readinto
    return self._sock.recv_into(b)
ConnectionResetError: [Errno 104] Connection reset by peer
----------------------------------------
[05/Feb/2020 22:51:33] code 400, message Bad HTTP/0.9 request type ('\x03\x00\x00/*à\x00\x00\x00\x00\x00Cookie:')
[05/Feb/2020 22:51:33] "  /*à     Cookie: mstshash=Administr" 400 -
[05/Feb/2020 22:51:34] code 400, message Bad HTTP/0.9 request type ('\x03\x00\x00/*à\x00\x00\x00\x00\x00Cookie:')
[05/Feb/2020 22:51:34] "  /*à     Cookie: mstshash=Administr" 400 -
Not Found: /
[06/Feb/2020 03:15:03] "GET / HTTP/1.0" 404 2032
Not Found: /
[06/Feb/2020 03:43:36] "GET / HTTP/1.1" 404 2031
Not Found: /
[06/Feb/2020 11:33:38] "GET / HTTP/1.1" 404 2031
Not Found: /ip.ws.126.net:443
[06/Feb/2020 19:21:49] "CONNECT ip.ws.126.net:443 HTTP/1.1" 404 1670
Not Found: /http:/123.125.114.144/
[06/Feb/2020 19:52:04] "HEAD http://123.125.114.144/ HTTP/1.1" 404 1682
[07/Feb/2020 04:16:43] "GET /uper/ HTTP/1.1" 200 543
Not Found: /favicon.ico
[07/Feb/2020 04:16:43] "GET /favicon.ico HTTP/1.1" 404 2082
Not Found: /favicon.ico
[07/Feb/2020 04:16:44] "GET /favicon.ico HTTP/1.1" 404 2082
[07/Feb/2020 04:16:47] "GET /uper/register/ HTTP/1.1" 200 525
[07/Feb/2020 04:17:08] "POST /uper/register_process/ HTTP/1.1" 302 0
[07/Feb/2020 04:17:08] "GET /uper/ HTTP/1.1" 200 543
[07/Feb/2020 04:17:11] "GET /uper/register/ HTTP/1.1" 200 525
[07/Feb/2020 04:17:17] "POST /uper/register_process/ HTTP/1.1" 302 0
[07/Feb/2020 04:17:18] "GET /uper/ HTTP/1.1" 200 543
[07/Feb/2020 04:17:19] "GET /uper/register/ HTTP/1.1" 200 525
[07/Feb/2020 04:17:27] "POST /uper/register_process/ HTTP/1.1" 302 0
[07/Feb/2020 04:17:27] "GET /uper/ HTTP/1.1" 200 543
[07/Feb/2020 04:17:29] "GET /uper/register/ HTTP/1.1" 200 525
[07/Feb/2020 04:17:38] "POST /uper/register_process/ HTTP/1.1" 302 0
[07/Feb/2020 04:17:38] "GET /uper/ HTTP/1.1" 200 543
[07/Feb/2020 04:17:38] "GET /uper/register/ HTTP/1.1" 200 525
[07/Feb/2020 04:17:47] "POST /uper/register_process/ HTTP/1.1" 302 0
[07/Feb/2020 04:17:47] "GET /uper/ HTTP/1.1" 200 543
[07/Feb/2020 04:17:49] "GET /uper/register/ HTTP/1.1" 200 525
[07/Feb/2020 04:17:56] "POST /uper/register_process/ HTTP/1.1" 302 0
[07/Feb/2020 04:17:56] "GET /uper/ HTTP/1.1" 200 543
[07/Feb/2020 04:17:57] "GET /uper/register/ HTTP/1.1" 200 525
[07/Feb/2020 04:18:03] "POST /uper/register_process/ HTTP/1.1" 302 0
[07/Feb/2020 04:18:03] "GET /uper/ HTTP/1.1" 200 543
[07/Feb/2020 04:18:04] "GET /uper/register/ HTTP/1.1" 200 525
[07/Feb/2020 04:18:15] "POST /uper/register_process/ HTTP/1.1" 302 0
[07/Feb/2020 04:18:15] "GET /uper/ HTTP/1.1" 200 543
[07/Feb/2020 04:18:17] "POST /uper/login/ HTTP/1.1" 302 0
[07/Feb/2020 04:18:17] "GET /uper/main_page/ HTTP/1.1" 200 2873
[07/Feb/2020 04:18:22] "GET /uper/register/ HTTP/1.1" 200 525
[07/Feb/2020 04:18:33] "POST /uper/register_process/ HTTP/1.1" 302 0
[07/Feb/2020 04:18:33] "GET /uper/ HTTP/1.1" 200 543
[07/Feb/2020 04:18:34] "GET /uper/register/ HTTP/1.1" 200 525
[07/Feb/2020 04:18:58] "POST /uper/register_process/ HTTP/1.1" 302 0
[07/Feb/2020 04:18:58] "GET /uper/ HTTP/1.1" 200 543
[07/Feb/2020 04:19:05] "POST /uper/login/ HTTP/1.1" 302 0
[07/Feb/2020 04:19:06] "GET /uper/main_page/ HTTP/1.1" 200 2881
[07/Feb/2020 04:19:11] "GET /uper/request_ride/ HTTP/1.1" 200 2799
/usr/local/lib/python3.6/dist-packages/django/db/models/fields/__init__.py:1364: RuntimeWarning: DateTimeField Personal_ride.called_time received a naive datetime (2020-02-07 04:19:26.949353) while time zone support is active.
  RuntimeWarning)
/usr/local/lib/python3.6/dist-packages/django/db/models/fields/__init__.py:1364: RuntimeWarning: DateTimeField Ride.arrival_datetime received a naive datetime (1121-02-11 02:12:00) while time zone support is active.
  RuntimeWarning)
[07/Feb/2020 04:19:26] "POST /uper/request_or_edit_ride_process/ HTTP/1.1" 302 0
[07/Feb/2020 04:19:27] "GET /uper/main_page/ HTTP/1.1" 200 3852
[07/Feb/2020 04:19:38] "GET /uper/ HTTP/1.1" 200 543
[07/Feb/2020 04:19:41] "GET /uper/register/ HTTP/1.1" 200 525
[07/Feb/2020 04:19:51] "POST /uper/logout/ HTTP/1.1" 302 0
[07/Feb/2020 04:19:51] "GET /uper/ HTTP/1.1" 200 543
[07/Feb/2020 04:20:08] "POST /uper/login/ HTTP/1.1" 200 27
[07/Feb/2020 04:20:12] "GET /uper/register/ HTTP/1.1" 200 525
[07/Feb/2020 04:20:18] "POST /uper/register_process/ HTTP/1.1" 302 0
[07/Feb/2020 04:20:18] "GET /uper/ HTTP/1.1" 200 543
[07/Feb/2020 04:20:26] "POST /uper/login/ HTTP/1.1" 302 0
[07/Feb/2020 04:20:26] "GET /uper/main_page/ HTTP/1.1" 200 2882
[07/Feb/2020 04:20:36] "GET /uper/share_ride_search/ HTTP/1.1" 200 663
/usr/local/lib/python3.6/dist-packages/django/db/models/fields/__init__.py:1364: RuntimeWarning: DateTimeField Ride.arrival_datetime received a naive datetime (9999-09-09 09:09:00) while time zone support is active.
  RuntimeWarning)
/usr/local/lib/python3.6/dist-packages/django/db/models/fields/__init__.py:1364: RuntimeWarning: DateTimeField Ride.arrival_datetime received a naive datetime (0001-01-01 00:00:00) while time zone support is active.
  RuntimeWarning)
[07/Feb/2020 04:21:01] "POST /uper/shareride_search_result/ HTTP/1.1" 200 1979
[07/Feb/2020 04:31:31] "POST /uper/join_shareride/ HTTP/1.1" 302 0
[07/Feb/2020 04:31:32] "GET /uper/main_page/ HTTP/1.1" 200 2882
[07/Feb/2020 04:31:36] "GET /uper/main_page/ HTTP/1.1" 200 2882
[07/Feb/2020 04:34:32] "GET /uper/share_ride_search/ HTTP/1.1" 200 663
/usr/local/lib/python3.6/dist-packages/django/db/models/fields/__init__.py:1364: RuntimeWarning: DateTimeField Ride.arrival_datetime received a naive datetime (9999-12-12 00:12:00) while time zone support is active.
  RuntimeWarning)
/usr/local/lib/python3.6/dist-packages/django/db/models/fields/__init__.py:1364: RuntimeWarning: DateTimeField Ride.arrival_datetime received a naive datetime (0001-12-12 00:12:00) while time zone support is active.
  RuntimeWarning)
[07/Feb/2020 04:34:51] "POST /uper/shareride_search_result/ HTTP/1.1" 200 1979
Watching for file changes with StatReloader
[07/Feb/2020 04:37:45] "POST /uper/shareride_search_result/ HTTP/1.1" 200 1979
[07/Feb/2020 04:38:44] "POST /uper/join_shareride/ HTTP/1.1" 302 0
[07/Feb/2020 04:38:44] "GET /uper/main_page/ HTTP/1.1" 200 2882
[07/Feb/2020 04:38:48] "GET /uper/driver_ride_search/ HTTP/1.1" 200 25
[07/Feb/2020 04:38:50] "GET /uper/share_ride_search/ HTTP/1.1" 200 663
/usr/local/lib/python3.6/dist-packages/django/db/models/fields/__init__.py:1364: RuntimeWarning: DateTimeField Ride.arrival_datetime received a naive datetime (0001-01-01 12:31:00) while time zone support is active.
  RuntimeWarning)
[07/Feb/2020 04:39:07] "POST /uper/shareride_search_result/ HTTP/1.1" 200 1979
[07/Feb/2020 04:39:19] "POST /uper/join_shareride/ HTTP/1.1" 302 0
[07/Feb/2020 04:39:19] "GET /uper/main_page/ HTTP/1.1" 200 2882
[07/Feb/2020 04:39:21] "GET /uper/share_ride_search/ HTTP/1.1" 200 663
/usr/local/lib/python3.6/dist-packages/django/db/models/fields/__init__.py:1364: RuntimeWarning: DateTimeField Ride.arrival_datetime received a naive datetime (9999-12-11 00:12:00) while time zone support is active.
  RuntimeWarning)
/usr/local/lib/python3.6/dist-packages/django/db/models/fields/__init__.py:1364: RuntimeWarning: DateTimeField Ride.arrival_datetime received a naive datetime (0010-01-01 11:11:00) while time zone support is active.
  RuntimeWarning)
[07/Feb/2020 04:39:39] "POST /uper/shareride_search_result/ HTTP/1.1" 200 1979
[07/Feb/2020 04:39:41] "POST /uper/join_shareride/ HTTP/1.1" 302 0
[07/Feb/2020 04:39:41] "GET /uper/main_page/ HTTP/1.1" 200 2882
/home/ubuntu/ece568/erss-hwk1-bh214/docker-deploy/web-app/uper/views.py changed, reloading.
Performing system checks...

System check identified no issues (0 silenced).
February 03, 2020 - 05:26:49
Django version 3.0.2, using settings 'mysite.settings'
Starting development server at http://0:8000/
Quit the server with CONTROL-C.
/home/ubuntu/ece568/erss-hwk1-bh214/docker-deploy/web-app/uper/views.py changed, reloading.
Performing system checks...

System check identified no issues (0 silenced).
February 07, 2020 - 04:36:14
Django version 3.0.2, using settings 'mysite.settings'
Starting development server at http://0:8080/
Quit the server with CONTROL-C.
Watching for file changes with StatReloader
Watching for file changes with StatReloader
Exception in thread django-main-thread:
Traceback (most recent call last):
  File "/usr/lib/python3.6/threading.py", line 916, in _bootstrap_inner
    self.run()
  File "/usr/lib/python3.6/threading.py", line 864, in run
    self._target(*self._args, **self._kwargs)
  File "/usr/local/lib/python3.6/dist-packages/django/utils/autoreload.py", line 53, in wrapper
    fn(*args, **kwargs)
  File "/usr/local/lib/python3.6/dist-packages/django/core/management/commands/runserver.py", line 117, in inner_run
    self.check(display_num_errors=True)
  File "/usr/local/lib/python3.6/dist-packages/django/core/management/base.py", line 395, in check
    include_deployment_checks=include_deployment_checks,
  File "/usr/local/lib/python3.6/dist-packages/django/core/management/base.py", line 382, in _run_checks
    return checks.run_checks(**kwargs)
  File "/usr/local/lib/python3.6/dist-packages/django/core/checks/registry.py", line 72, in run_checks
    new_errors = check(app_configs=app_configs)
  File "/usr/local/lib/python3.6/dist-packages/django/core/checks/urls.py", line 13, in check_url_config
    return check_resolver(resolver)
  File "/usr/local/lib/python3.6/dist-packages/django/core/checks/urls.py", line 23, in check_resolver
    return check_method()
  File "/usr/local/lib/python3.6/dist-packages/django/urls/resolvers.py", line 407, in check
    for pattern in self.url_patterns:
  File "/usr/local/lib/python3.6/dist-packages/django/utils/functional.py", line 48, in __get__
    res = instance.__dict__[self.name] = self.func(instance)
  File "/usr/local/lib/python3.6/dist-packages/django/urls/resolvers.py", line 588, in url_patterns
    patterns = getattr(self.urlconf_module, "urlpatterns", self.urlconf_module)
  File "/usr/local/lib/python3.6/dist-packages/django/utils/functional.py", line 48, in __get__
    res = instance.__dict__[self.name] = self.func(instance)
  File "/usr/local/lib/python3.6/dist-packages/django/urls/resolvers.py", line 581, in urlconf_module
    return import_module(self.urlconf_name)
  File "/usr/lib/python3.6/importlib/__init__.py", line 126, in import_module
    return _bootstrap._gcd_import(name[level:], package, level)
  File "<frozen importlib._bootstrap>", line 994, in _gcd_import
  File "<frozen importlib._bootstrap>", line 971, in _find_and_load
  File "<frozen importlib._bootstrap>", line 955, in _find_and_load_unlocked
  File "<frozen importlib._bootstrap>", line 665, in _load_unlocked
  File "<frozen importlib._bootstrap_external>", line 678, in exec_module
  File "<frozen importlib._bootstrap>", line 219, in _call_with_frames_removed
  File "/home/ubuntu/ece568/erss-hwk1-bh214/docker-deploy/web-app/mysite/urls.py", line 21, in <module>
    path('uper/', include('uper.urls')),
  File "/usr/local/lib/python3.6/dist-packages/django/urls/conf.py", line 34, in include
    urlconf_module = import_module(urlconf_module)
  File "/usr/lib/python3.6/importlib/__init__.py", line 126, in import_module
    return _bootstrap._gcd_import(name[level:], package, level)
  File "<frozen importlib._bootstrap>", line 994, in _gcd_import
  File "<frozen importlib._bootstrap>", line 971, in _find_and_load
  File "<frozen importlib._bootstrap>", line 955, in _find_and_load_unlocked
  File "<frozen importlib._bootstrap>", line 665, in _load_unlocked
  File "<frozen importlib._bootstrap_external>", line 678, in exec_module
  File "<frozen importlib._bootstrap>", line 219, in _call_with_frames_removed
  File "/home/ubuntu/ece568/erss-hwk1-bh214/docker-deploy/web-app/uper/urls.py", line 3, in <module>
    from . import views
  File "/home/ubuntu/ece568/erss-hwk1-bh214/docker-deploy/web-app/uper/views.py", line 310
    personal_ride = Personal_ride(
    ^
IndentationError: unexpected indent

/home/ubuntu/ece568/erss-hwk1-bh214/docker-deploy/web-app/uper/views.py changed, reloading.
Performing system checks...

Watching for file changes with StatReloader
Exception in thread django-main-thread:
Traceback (most recent call last):
  File "/usr/lib/python3.6/threading.py", line 916, in _bootstrap_inner
    self.run()
  File "/usr/lib/python3.6/threading.py", line 864, in run
    self._target(*self._args, **self._kwargs)
  File "/usr/local/lib/python3.6/dist-packages/django/utils/autoreload.py", line 53, in wrapper
    fn(*args, **kwargs)
  File "/usr/local/lib/python3.6/dist-packages/django/core/management/commands/runserver.py", line 117, in inner_run
    self.check(display_num_errors=True)
  File "/usr/local/lib/python3.6/dist-packages/django/core/management/base.py", line 395, in check
    include_deployment_checks=include_deployment_checks,
  File "/usr/local/lib/python3.6/dist-packages/django/core/management/base.py", line 382, in _run_checks
    return checks.run_checks(**kwargs)
  File "/usr/local/lib/python3.6/dist-packages/django/core/checks/registry.py", line 72, in run_checks
    new_errors = check(app_configs=app_configs)
  File "/usr/local/lib/python3.6/dist-packages/django/core/checks/urls.py", line 13, in check_url_config
    return check_resolver(resolver)
  File "/usr/local/lib/python3.6/dist-packages/django/core/checks/urls.py", line 23, in check_resolver
    return check_method()
  File "/usr/local/lib/python3.6/dist-packages/django/urls/resolvers.py", line 407, in check
    for pattern in self.url_patterns:
  File "/usr/local/lib/python3.6/dist-packages/django/utils/functional.py", line 48, in __get__
    res = instance.__dict__[self.name] = self.func(instance)
  File "/usr/local/lib/python3.6/dist-packages/django/urls/resolvers.py", line 588, in url_patterns
    patterns = getattr(self.urlconf_module, "urlpatterns", self.urlconf_module)
  File "/usr/local/lib/python3.6/dist-packages/django/utils/functional.py", line 48, in __get__
    res = instance.__dict__[self.name] = self.func(instance)
  File "/usr/local/lib/python3.6/dist-packages/django/urls/resolvers.py", line 581, in urlconf_module
    return import_module(self.urlconf_name)
  File "/usr/lib/python3.6/importlib/__init__.py", line 126, in import_module
    return _bootstrap._gcd_import(name[level:], package, level)
  File "<frozen importlib._bootstrap>", line 994, in _gcd_import
  File "<frozen importlib._bootstrap>", line 971, in _find_and_load
  File "<frozen importlib._bootstrap>", line 955, in _find_and_load_unlocked
  File "<frozen importlib._bootstrap>", line 665, in _load_unlocked
  File "<frozen importlib._bootstrap_external>", line 678, in exec_module
  File "<frozen importlib._bootstrap>", line 219, in _call_with_frames_removed
  File "/home/ubuntu/ece568/erss-hwk1-bh214/docker-deploy/web-app/mysite/urls.py", line 21, in <module>
    path('uper/', include('uper.urls')),
  File "/usr/local/lib/python3.6/dist-packages/django/urls/conf.py", line 34, in include
    urlconf_module = import_module(urlconf_module)
  File "/usr/lib/python3.6/importlib/__init__.py", line 126, in import_module
    return _bootstrap._gcd_import(name[level:], package, level)
  File "<frozen importlib._bootstrap>", line 994, in _gcd_import
  File "<frozen importlib._bootstrap>", line 971, in _find_and_load
  File "<frozen importlib._bootstrap>", line 955, in _find_and_load_unlocked
  File "<frozen importlib._bootstrap>", line 665, in _load_unlocked
  File "<frozen importlib._bootstrap_external>", line 678, in exec_module
  File "<frozen importlib._bootstrap>", line 219, in _call_with_frames_removed
  File "/home/ubuntu/ece568/erss-hwk1-bh214/docker-deploy/web-app/uper/urls.py", line 3, in <module>
    from . import views
  File "/home/ubuntu/ece568/erss-hwk1-bh214/docker-deploy/web-app/uper/views.py", line 310
    personal_ride = Personal_ride(
    ^
IndentationError: unexpected indent

/home/ubuntu/ece568/erss-hwk1-bh214/docker-deploy/web-app/uper/views.py changed, reloading.
Performing system checks...

Watching for file changes with StatReloader
/home/ubuntu/ece568/erss-hwk1-bh214/docker-deploy/web-app/uper/views.py changed, reloading.
Performing system checks...

System check identified no issues (0 silenced).
February 07, 2020 - 04:42:38
Django version 3.0.2, using settings 'mysite.settings'
Starting development server at http://0:8000/
Quit the server with CONTROL-C.
/home/ubuntu/ece568/erss-hwk1-bh214/docker-deploy/web-app/uper/views.py changed, reloading.
Performing system checks...

System check identified no issues (0 silenced).
February 07, 2020 - 04:42:37
Django version 3.0.2, using settings 'mysite.settings'
Starting development server at http://0:8080/
Quit the server with CONTROL-C.
Watching for file changes with StatReloader
Watching for file changes with StatReloader
/home/ubuntu/ece568/erss-hwk1-bh214/docker-deploy/web-app/uper/views.py changed, reloading.
Performing system checks...

System check identified no issues (0 silenced).
February 07, 2020 - 04:42:59
Django version 3.0.2, using settings 'mysite.settings'
Starting development server at http://0:8000/
Quit the server with CONTROL-C.
/home/ubuntu/ece568/erss-hwk1-bh214/docker-deploy/web-app/uper/views.py changed, reloading.
Performing system checks...

System check identified no issues (0 silenced).
February 07, 2020 - 04:43:00
Django version 3.0.2, using settings 'mysite.settings'
Starting development server at http://0:8080/
Quit the server with CONTROL-C.
Watching for file changes with StatReloader
Watching for file changes with StatReloader
/home/ubuntu/ece568/erss-hwk1-bh214/docker-deploy/web-app/uper/views.py changed, reloading.
Performing system checks...

System check identified no issues (0 silenced).
February 07, 2020 - 04:43:37
Django version 3.0.2, using settings 'mysite.settings'
Starting development server at http://0:8000/
Quit the server with CONTROL-C.
Watching for file changes with StatReloader
/home/ubuntu/ece568/erss-hwk1-bh214/docker-deploy/web-app/uper/views.py changed, reloading.
Performing system checks...

System check identified no issues (0 silenced).
February 07, 2020 - 04:43:38
Django version 3.0.2, using settings 'mysite.settings'
Starting development server at http://0:8080/
Quit the server with CONTROL-C.
Watching for file changes with StatReloader
/home/ubuntu/ece568/erss-hwk1-bh214/docker-deploy/web-app/uper/views.py changed, reloading.
Performing system checks...

System check identified no issues (0 silenced).
February 07, 2020 - 04:43:50
Django version 3.0.2, using settings 'mysite.settings'
Starting development server at http://0:8080/
Quit the server with CONTROL-C.
Watching for file changes with StatReloader
/home/ubuntu/ece568/erss-hwk1-bh214/docker-deploy/web-app/uper/views.py changed, reloading.
Performing system checks...

System check identified no issues (0 silenced).
February 07, 2020 - 04:43:49
Django version 3.0.2, using settings 'mysite.settings'
Starting development server at http://0:8000/
Quit the server with CONTROL-C.
Watching for file changes with StatReloader
/home/ubuntu/ece568/erss-hwk1-bh214/docker-deploy/web-app/uper/views.py changed, reloading.
Performing system checks...

System check identified no issues (0 silenced).
February 07, 2020 - 04:43:57
Django version 3.0.2, using settings 'mysite.settings'
Starting development server at http://0:8000/
Quit the server with CONTROL-C.
Watching for file changes with StatReloader
/home/ubuntu/ece568/erss-hwk1-bh214/docker-deploy/web-app/uper/views.py changed, reloading.
Performing system checks...

System check identified no issues (0 silenced).
February 07, 2020 - 04:43:56
Django version 3.0.2, using settings 'mysite.settings'
Starting development server at http://0:8080/
Quit the server with CONTROL-C.
Watching for file changes with StatReloader
/home/ubuntu/ece568/erss-hwk1-bh214/docker-deploy/web-app/uper/views.py changed, reloading.
Performing system checks...

System check identified no issues (0 silenced).
February 07, 2020 - 04:44:15
Django version 3.0.2, using settings 'mysite.settings'
Starting development server at http://0:8080/
Quit the server with CONTROL-C.
Watching for file changes with StatReloader
/home/ubuntu/ece568/erss-hwk1-bh214/docker-deploy/web-app/uper/views.py changed, reloading.
Performing system checks...

System check identified no issues (0 silenced).
February 07, 2020 - 04:44:14
Django version 3.0.2, using settings 'mysite.settings'
Starting development server at http://0:8000/
Quit the server with CONTROL-C.
Watching for file changes with StatReloader
/home/ubuntu/ece568/erss-hwk1-bh214/docker-deploy/web-app/uper/views.py changed, reloading.
Performing system checks...

System check identified no issues (0 silenced).
February 07, 2020 - 04:44:25
Django version 3.0.2, using settings 'mysite.settings'
Starting development server at http://0:8000/
Quit the server with CONTROL-C.
Watching for file changes with StatReloader
/home/ubuntu/ece568/erss-hwk1-bh214/docker-deploy/web-app/uper/views.py changed, reloading.
Performing system checks...

System check identified no issues (0 silenced).
February 07, 2020 - 04:44:24
Django version 3.0.2, using settings 'mysite.settings'
Starting development server at http://0:8080/
Quit the server with CONTROL-C.
Watching for file changes with StatReloader
/home/ubuntu/ece568/erss-hwk1-bh214/docker-deploy/web-app/uper/views.py changed, reloading.
Performing system checks...

System check identified no issues (0 silenced).
February 07, 2020 - 04:45:02
Django version 3.0.2, using settings 'mysite.settings'
Starting development server at http://0:8000/
Quit the server with CONTROL-C.
Watching for file changes with StatReloader
/home/ubuntu/ece568/erss-hwk1-bh214/docker-deploy/web-app/uper/views.py changed, reloading.
Performing system checks...

System check identified no issues (0 silenced).
February 07, 2020 - 04:45:02
Django version 3.0.2, using settings 'mysite.settings'
Starting development server at http://0:8080/
Quit the server with CONTROL-C.
Watching for file changes with StatReloader
/home/ubuntu/ece568/erss-hwk1-bh214/docker-deploy/web-app/uper/views.py changed, reloading.
Performing system checks...

System check identified no issues (0 silenced).
February 07, 2020 - 04:45:29
Django version 3.0.2, using settings 'mysite.settings'
Starting development server at http://0:8080/
Quit the server with CONTROL-C.
Watching for file changes with StatReloader
/home/ubuntu/ece568/erss-hwk1-bh214/docker-deploy/web-app/uper/views.py changed, reloading.
Performing system checks...

System check identified no issues (0 silenced).
February 07, 2020 - 04:45:28
Django version 3.0.2, using settings 'mysite.settings'
Starting development server at http://0:8000/
Quit the server with CONTROL-C.
Watching for file changes with StatReloader
/home/ubuntu/ece568/erss-hwk1-bh214/docker-deploy/web-app/uper/views.py changed, reloading.
Performing system checks...

System check identified no issues (0 silenced).
February 07, 2020 - 04:45:49
Django version 3.0.2, using settings 'mysite.settings'
Starting development server at http://0:8080/
Quit the server with CONTROL-C.
Watching for file changes with StatReloader
/home/ubuntu/ece568/erss-hwk1-bh214/docker-deploy/web-app/uper/views.py changed, reloading.
Performing system checks...

System check identified no issues (0 silenced).
February 07, 2020 - 04:45:49
Django version 3.0.2, using settings 'mysite.settings'
Starting development server at http://0:8000/
Quit the server with CONTROL-C.
Watching for file changes with StatReloader
[07/Feb/2020 04:46:10] "GET /uper/share_ride_search/ HTTP/1.1" 200 663
/usr/local/lib/python3.6/dist-packages/django/db/models/fields/__init__.py:1364: RuntimeWarning: DateTimeField Ride.arrival_datetime received a naive datetime (9999-09-09 09:09:00) while time zone support is active.
  RuntimeWarning)
/usr/local/lib/python3.6/dist-packages/django/db/models/fields/__init__.py:1364: RuntimeWarning: DateTimeField Ride.arrival_datetime received a naive datetime (0001-01-01 11:11:00) while time zone support is active.
  RuntimeWarning)
[07/Feb/2020 04:46:26] "POST /uper/shareride_search_result/ HTTP/1.1" 200 1979
Internal Server Error: /uper/join_shareride/
Traceback (most recent call last):
  File "/usr/local/lib/python3.6/dist-packages/django/core/handlers/exception.py", line 34, in inner
    response = get_response(request)
  File "/usr/local/lib/python3.6/dist-packages/django/core/handlers/base.py", line 115, in _get_response
    response = self.process_exception_by_middleware(e, request)
  File "/usr/local/lib/python3.6/dist-packages/django/core/handlers/base.py", line 113, in _get_response
    response = wrapped_callback(request, *callback_args, **callback_kwargs)
  File "/home/ubuntu/ece568/erss-hwk1-bh214/docker-deploy/web-app/uper/views.py", line 325, in join_shareride
    ride.personal_ride_set.add(presonal_ride)
NameError: name 'presonal_ride' is not defined
[07/Feb/2020 04:46:30] "POST /uper/join_shareride/ HTTP/1.1" 500 66781
/home/ubuntu/ece568/erss-hwk1-bh214/docker-deploy/web-app/uper/views.py changed, reloading.
Performing system checks...

System check identified no issues (0 silenced).
February 07, 2020 - 04:46:00
Django version 3.0.2, using settings 'mysite.settings'
Starting development server at http://0:8000/
Quit the server with CONTROL-C.
/home/ubuntu/ece568/erss-hwk1-bh214/docker-deploy/web-app/uper/views.py changed, reloading.
Performing system checks...

System check identified no issues (0 silenced).
February 07, 2020 - 04:46:00
Django version 3.0.2, using settings 'mysite.settings'
Starting development server at http://0:8080/
Quit the server with CONTROL-C.
Watching for file changes with StatReloader
Watching for file changes with StatReloader
/usr/local/lib/python3.6/dist-packages/django/db/models/fields/__init__.py:1364: RuntimeWarning: DateTimeField Personal_ride.called_time received a naive datetime (2020-02-07 04:47:00.931392) while time zone support is active.
  RuntimeWarning)
Internal Server Error: /uper/join_shareride/
Traceback (most recent call last):
  File "/usr/local/lib/python3.6/dist-packages/django/core/handlers/exception.py", line 34, in inner
    response = get_response(request)
  File "/usr/local/lib/python3.6/dist-packages/django/core/handlers/base.py", line 115, in _get_response
    response = self.process_exception_by_middleware(e, request)
  File "/usr/local/lib/python3.6/dist-packages/django/core/handlers/base.py", line 113, in _get_response
    response = wrapped_callback(request, *callback_args, **callback_kwargs)
  File "/home/ubuntu/ece568/erss-hwk1-bh214/docker-deploy/web-app/uper/views.py", line 326, in join_shareride
    ride.personal_ride_set.add(presonal_ride)
NameError: name 'presonal_ride' is not defined
[07/Feb/2020 04:47:00] "POST /uper/join_shareride/ HTTP/1.1" 500 66779
/usr/local/lib/python3.6/dist-packages/django/db/models/fields/__init__.py:1364: RuntimeWarning: DateTimeField Personal_ride.called_time received a naive datetime (2020-02-07 04:47:10.462539) while time zone support is active.
  RuntimeWarning)
Internal Server Error: /uper/join_shareride/
Traceback (most recent call last):
  File "/usr/local/lib/python3.6/dist-packages/django/core/handlers/exception.py", line 34, in inner
    response = get_response(request)
  File "/usr/local/lib/python3.6/dist-packages/django/core/handlers/base.py", line 115, in _get_response
    response = self.process_exception_by_middleware(e, request)
  File "/usr/local/lib/python3.6/dist-packages/django/core/handlers/base.py", line 113, in _get_response
    response = wrapped_callback(request, *callback_args, **callback_kwargs)
  File "/home/ubuntu/ece568/erss-hwk1-bh214/docker-deploy/web-app/uper/views.py", line 326, in join_shareride
    ride.personal_ride_set.add(presonal_ride)
NameError: name 'presonal_ride' is not defined
[07/Feb/2020 04:47:10] "POST /uper/join_shareride/ HTTP/1.1" 500 66779
/home/ubuntu/ece568/erss-hwk1-bh214/docker-deploy/web-app/uper/views.py changed, reloading.
Performing system checks...

System check identified no issues (0 silenced).
February 07, 2020 - 04:46:58
Django version 3.0.2, using settings 'mysite.settings'
Starting development server at http://0:8000/
Quit the server with CONTROL-C.
/home/ubuntu/ece568/erss-hwk1-bh214/docker-deploy/web-app/uper/views.py changed, reloading.
Performing system checks...

System check identified no issues (0 silenced).
February 07, 2020 - 04:46:59
Django version 3.0.2, using settings 'mysite.settings'
Starting development server at http://0:8080/
Quit the server with CONTROL-C.
Watching for file changes with StatReloader
Watching for file changes with StatReloader
/usr/local/lib/python3.6/dist-packages/django/db/models/fields/__init__.py:1364: RuntimeWarning: DateTimeField Personal_ride.called_time received a naive datetime (2020-02-07 04:47:27.088358) while time zone support is active.
  RuntimeWarning)
[07/Feb/2020 04:47:27] "POST /uper/join_shareride/ HTTP/1.1" 302 0
[07/Feb/2020 04:47:27] "GET /uper/main_page/ HTTP/1.1" 200 4522
[07/Feb/2020 04:47:42] "POST /uper/logout/ HTTP/1.1" 302 0
[07/Feb/2020 04:47:42] "GET /uper/ HTTP/1.1" 200 543
[07/Feb/2020 04:47:47] "POST /uper/login/ HTTP/1.1" 200 27
[07/Feb/2020 04:47:49] "GET /uper/register/ HTTP/1.1" 200 525
[07/Feb/2020 04:48:00] "POST /uper/register_process/ HTTP/1.1" 302 0
[07/Feb/2020 04:48:00] "GET /uper/ HTTP/1.1" 200 543
[07/Feb/2020 04:48:08] "POST /uper/login/ HTTP/1.1" 302 0
[07/Feb/2020 04:48:08] "GET /uper/main_page/ HTTP/1.1" 200 2882
[07/Feb/2020 04:48:16] "GET /uper/share_ride_search/ HTTP/1.1" 200 663
/usr/local/lib/python3.6/dist-packages/django/db/models/fields/__init__.py:1364: RuntimeWarning: DateTimeField Ride.arrival_datetime received a naive datetime (9999-09-09 00:12:00) while time zone support is active.
  RuntimeWarning)
/usr/local/lib/python3.6/dist-packages/django/db/models/fields/__init__.py:1364: RuntimeWarning: DateTimeField Ride.arrival_datetime received a naive datetime (0001-01-01 00:12:00) while time zone support is active.
  RuntimeWarning)
[07/Feb/2020 04:48:33] "POST /uper/shareride_search_result/ HTTP/1.1" 200 1979
/usr/local/lib/python3.6/dist-packages/django/db/models/fields/__init__.py:1364: RuntimeWarning: DateTimeField Personal_ride.called_time received a naive datetime (2020-02-07 04:48:36.224763) while time zone support is active.
  RuntimeWarning)
[07/Feb/2020 04:48:36] "POST /uper/join_shareride/ HTTP/1.1" 302 0
[07/Feb/2020 04:48:36] "GET /uper/main_page/ HTTP/1.1" 200 3491
[07/Feb/2020 04:49:16] "GET /uper/request_ride/ HTTP/1.1" 200 2799
/usr/local/lib/python3.6/dist-packages/django/db/models/fields/__init__.py:1364: RuntimeWarning: DateTimeField Personal_ride.called_time received a naive datetime (2020-02-07 04:49:48.507004) while time zone support is active.
  RuntimeWarning)
/usr/local/lib/python3.6/dist-packages/django/db/models/fields/__init__.py:1364: RuntimeWarning: DateTimeField Ride.arrival_datetime received a naive datetime (2020-09-09 00:12:00) while time zone support is active.
  RuntimeWarning)
[07/Feb/2020 04:49:48] "POST /uper/request_or_edit_ride_process/ HTTP/1.1" 302 0
[07/Feb/2020 04:49:48] "GET /uper/main_page/ HTTP/1.1" 200 4466
[07/Feb/2020 04:49:54] "POST /uper/edit_ride/ HTTP/1.1" 200 2023
/usr/local/lib/python3.6/dist-packages/django/db/models/fields/__init__.py:1364: RuntimeWarning: DateTimeField Ride.arrival_datetime received a naive datetime (2020-09-09 12:12:00) while time zone support is active.
  RuntimeWarning)
[07/Feb/2020 04:50:04] "POST /uper/request_or_edit_ride_process/ HTTP/1.1" 302 0
[07/Feb/2020 04:50:04] "GET /uper/main_page/ HTTP/1.1" 200 4466
/home/ubuntu/ece568/erss-hwk1-bh214/docker-deploy/web-app/uper/views.py changed, reloading.
Performing system checks...

System check identified no issues (0 silenced).
February 07, 2020 - 04:47:25
Django version 3.0.2, using settings 'mysite.settings'
Starting development server at http://0:8000/
Quit the server with CONTROL-C.
/home/ubuntu/ece568/erss-hwk1-bh214/docker-deploy/web-app/uper/views.py changed, reloading.
Performing system checks...

System check identified no issues (0 silenced).
February 07, 2020 - 04:47:25
Django version 3.0.2, using settings 'mysite.settings'
Starting development server at http://0:8080/
Quit the server with CONTROL-C.
Watching for file changes with StatReloader
Watching for file changes with StatReloader
/home/ubuntu/ece568/erss-hwk1-bh214/docker-deploy/web-app/uper/views.py changed, reloading.
Performing system checks...

System check identified no issues (0 silenced).
February 07, 2020 - 04:51:55
Django version 3.0.2, using settings 'mysite.settings'
Starting development server at http://0:8000/
Quit the server with CONTROL-C.
/home/ubuntu/ece568/erss-hwk1-bh214/docker-deploy/web-app/uper/views.py changed, reloading.
Performing system checks...

System check identified no issues (0 silenced).
February 07, 2020 - 04:51:55
Django version 3.0.2, using settings 'mysite.settings'
Starting development server at http://0:8080/
Quit the server with CONTROL-C.
Watching for file changes with StatReloader
Watching for file changes with StatReloader
/home/ubuntu/ece568/erss-hwk1-bh214/docker-deploy/web-app/uper/views.py changed, reloading.
Performing system checks...

System check identified no issues (0 silenced).
February 07, 2020 - 04:52:03
Django version 3.0.2, using settings 'mysite.settings'
Starting development server at http://0:8080/
Quit the server with CONTROL-C.
Watching for file changes with StatReloader
/home/ubuntu/ece568/erss-hwk1-bh214/docker-deploy/web-app/uper/views.py changed, reloading.
Performing system checks...

System check identified no issues (0 silenced).
February 07, 2020 - 04:52:03
Django version 3.0.2, using settings 'mysite.settings'
Starting development server at http://0:8000/
Quit the server with CONTROL-C.
Watching for file changes with StatReloader
/home/ubuntu/ece568/erss-hwk1-bh214/docker-deploy/web-app/uper/views.py changed, reloading.
Performing system checks...

System check identified no issues (0 silenced).
February 07, 2020 - 04:52:20
Django version 3.0.2, using settings 'mysite.settings'
Starting development server at http://0:8080/
Quit the server with CONTROL-C.
Watching for file changes with StatReloader
/home/ubuntu/ece568/erss-hwk1-bh214/docker-deploy/web-app/uper/views.py changed, reloading.
Performing system checks...

System check identified no issues (0 silenced).
February 07, 2020 - 04:52:21
Django version 3.0.2, using settings 'mysite.settings'
Starting development server at http://0:8000/
Quit the server with CONTROL-C.
Watching for file changes with StatReloader
/home/ubuntu/ece568/erss-hwk1-bh214/docker-deploy/web-app/uper/views.py changed, reloading.
Performing system checks...

System check identified no issues (0 silenced).
February 07, 2020 - 04:52:25
Django version 3.0.2, using settings 'mysite.settings'
Starting development server at http://0:8080/
Quit the server with CONTROL-C.
Watching for file changes with StatReloader
/home/ubuntu/ece568/erss-hwk1-bh214/docker-deploy/web-app/uper/views.py changed, reloading.
Performing system checks...

System check identified no issues (0 silenced).
February 07, 2020 - 04:52:25
Django version 3.0.2, using settings 'mysite.settings'
Starting development server at http://0:8000/
Quit the server with CONTROL-C.
Watching for file changes with StatReloader
Exception in thread django-main-thread:
Traceback (most recent call last):
  File "/usr/lib/python3.6/threading.py", line 916, in _bootstrap_inner
    self.run()
  File "/usr/lib/python3.6/threading.py", line 864, in run
    self._target(*self._args, **self._kwargs)
  File "/usr/local/lib/python3.6/dist-packages/django/utils/autoreload.py", line 53, in wrapper
    fn(*args, **kwargs)
  File "/usr/local/lib/python3.6/dist-packages/django/core/management/commands/runserver.py", line 117, in inner_run
    self.check(display_num_errors=True)
  File "/usr/local/lib/python3.6/dist-packages/django/core/management/base.py", line 395, in check
    include_deployment_checks=include_deployment_checks,
  File "/usr/local/lib/python3.6/dist-packages/django/core/management/base.py", line 382, in _run_checks
    return checks.run_checks(**kwargs)
  File "/usr/local/lib/python3.6/dist-packages/django/core/checks/registry.py", line 72, in run_checks
    new_errors = check(app_configs=app_configs)
  File "/usr/local/lib/python3.6/dist-packages/django/core/checks/urls.py", line 13, in check_url_config
    return check_resolver(resolver)
  File "/usr/local/lib/python3.6/dist-packages/django/core/checks/urls.py", line 23, in check_resolver
    return check_method()
  File "/usr/local/lib/python3.6/dist-packages/django/urls/resolvers.py", line 407, in check
    for pattern in self.url_patterns:
  File "/usr/local/lib/python3.6/dist-packages/django/utils/functional.py", line 48, in __get__
    res = instance.__dict__[self.name] = self.func(instance)
  File "/usr/local/lib/python3.6/dist-packages/django/urls/resolvers.py", line 588, in url_patterns
    patterns = getattr(self.urlconf_module, "urlpatterns", self.urlconf_module)
  File "/usr/local/lib/python3.6/dist-packages/django/utils/functional.py", line 48, in __get__
    res = instance.__dict__[self.name] = self.func(instance)
  File "/usr/local/lib/python3.6/dist-packages/django/urls/resolvers.py", line 581, in urlconf_module
    return import_module(self.urlconf_name)
  File "/usr/lib/python3.6/importlib/__init__.py", line 126, in import_module
    return _bootstrap._gcd_import(name[level:], package, level)
  File "<frozen importlib._bootstrap>", line 994, in _gcd_import
  File "<frozen importlib._bootstrap>", line 971, in _find_and_load
  File "<frozen importlib._bootstrap>", line 955, in _find_and_load_unlocked
  File "<frozen importlib._bootstrap>", line 665, in _load_unlocked
  File "<frozen importlib._bootstrap_external>", line 678, in exec_module
  File "<frozen importlib._bootstrap>", line 219, in _call_with_frames_removed
  File "/home/ubuntu/ece568/erss-hwk1-bh214/docker-deploy/web-app/mysite/urls.py", line 21, in <module>
    path('uper/', include('uper.urls')),
  File "/usr/local/lib/python3.6/dist-packages/django/urls/conf.py", line 34, in include
    urlconf_module = import_module(urlconf_module)
  File "/usr/lib/python3.6/importlib/__init__.py", line 126, in import_module
    return _bootstrap._gcd_import(name[level:], package, level)
  File "<frozen importlib._bootstrap>", line 994, in _gcd_import
  File "<frozen importlib._bootstrap>", line 971, in _find_and_load
  File "<frozen importlib._bootstrap>", line 955, in _find_and_load_unlocked
  File "<frozen importlib._bootstrap>", line 665, in _load_unlocked
  File "<frozen importlib._bootstrap_external>", line 678, in exec_module
  File "<frozen importlib._bootstrap>", line 219, in _call_with_frames_removed
  File "/home/ubuntu/ece568/erss-hwk1-bh214/docker-deploy/web-app/uper/urls.py", line 3, in <module>
    from . import views
  File "/home/ubuntu/ece568/erss-hwk1-bh214/docker-deploy/web-app/uper/views.py", line 356
    personal_ride.save()
    ^
IndentationError: unexpected indent

/home/ubuntu/ece568/erss-hwk1-bh214/docker-deploy/web-app/uper/views.py changed, reloading.
Performing system checks...

Watching for file changes with StatReloader
Exception in thread django-main-thread:
Traceback (most recent call last):
  File "/usr/lib/python3.6/threading.py", line 916, in _bootstrap_inner
    self.run()
  File "/usr/lib/python3.6/threading.py", line 864, in run
    self._target(*self._args, **self._kwargs)
  File "/usr/local/lib/python3.6/dist-packages/django/utils/autoreload.py", line 53, in wrapper
    fn(*args, **kwargs)
  File "/usr/local/lib/python3.6/dist-packages/django/core/management/commands/runserver.py", line 117, in inner_run
    self.check(display_num_errors=True)
  File "/usr/local/lib/python3.6/dist-packages/django/core/management/base.py", line 395, in check
    include_deployment_checks=include_deployment_checks,
  File "/usr/local/lib/python3.6/dist-packages/django/core/management/base.py", line 382, in _run_checks
    return checks.run_checks(**kwargs)
  File "/usr/local/lib/python3.6/dist-packages/django/core/checks/registry.py", line 72, in run_checks
    new_errors = check(app_configs=app_configs)
  File "/usr/local/lib/python3.6/dist-packages/django/core/checks/urls.py", line 13, in check_url_config
    return check_resolver(resolver)
  File "/usr/local/lib/python3.6/dist-packages/django/core/checks/urls.py", line 23, in check_resolver
    return check_method()
  File "/usr/local/lib/python3.6/dist-packages/django/urls/resolvers.py", line 407, in check
    for pattern in self.url_patterns:
  File "/usr/local/lib/python3.6/dist-packages/django/utils/functional.py", line 48, in __get__
    res = instance.__dict__[self.name] = self.func(instance)
  File "/usr/local/lib/python3.6/dist-packages/django/urls/resolvers.py", line 588, in url_patterns
    patterns = getattr(self.urlconf_module, "urlpatterns", self.urlconf_module)
  File "/usr/local/lib/python3.6/dist-packages/django/utils/functional.py", line 48, in __get__
    res = instance.__dict__[self.name] = self.func(instance)
  File "/usr/local/lib/python3.6/dist-packages/django/urls/resolvers.py", line 581, in urlconf_module
    return import_module(self.urlconf_name)
  File "/usr/lib/python3.6/importlib/__init__.py", line 126, in import_module
    return _bootstrap._gcd_import(name[level:], package, level)
  File "<frozen importlib._bootstrap>", line 994, in _gcd_import
  File "<frozen importlib._bootstrap>", line 971, in _find_and_load
  File "<frozen importlib._bootstrap>", line 955, in _find_and_load_unlocked
  File "<frozen importlib._bootstrap>", line 665, in _load_unlocked
  File "<frozen importlib._bootstrap_external>", line 678, in exec_module
  File "<frozen importlib._bootstrap>", line 219, in _call_with_frames_removed
  File "/home/ubuntu/ece568/erss-hwk1-bh214/docker-deploy/web-app/mysite/urls.py", line 21, in <module>
    path('uper/', include('uper.urls')),
  File "/usr/local/lib/python3.6/dist-packages/django/urls/conf.py", line 34, in include
    urlconf_module = import_module(urlconf_module)
  File "/usr/lib/python3.6/importlib/__init__.py", line 126, in import_module
    return _bootstrap._gcd_import(name[level:], package, level)
  File "<frozen importlib._bootstrap>", line 994, in _gcd_import
  File "<frozen importlib._bootstrap>", line 971, in _find_and_load
  File "<frozen importlib._bootstrap>", line 955, in _find_and_load_unlocked
  File "<frozen importlib._bootstrap>", line 665, in _load_unlocked
  File "<frozen importlib._bootstrap_external>", line 678, in exec_module
  File "<frozen importlib._bootstrap>", line 219, in _call_with_frames_removed
  File "/home/ubuntu/ece568/erss-hwk1-bh214/docker-deploy/web-app/uper/urls.py", line 3, in <module>
    from . import views
  File "/home/ubuntu/ece568/erss-hwk1-bh214/docker-deploy/web-app/uper/views.py", line 356
    personal_ride.save()
    ^
IndentationError: unexpected indent

/home/ubuntu/ece568/erss-hwk1-bh214/docker-deploy/web-app/uper/views.py changed, reloading.
Performing system checks...

Watching for file changes with StatReloader
/home/ubuntu/ece568/erss-hwk1-bh214/docker-deploy/web-app/uper/views.py changed, reloading.
Performing system checks...

System check identified no issues (0 silenced).
February 07, 2020 - 04:52:48
Django version 3.0.2, using settings 'mysite.settings'
Starting development server at http://0:8000/
Quit the server with CONTROL-C.
Watching for file changes with StatReloader
/home/ubuntu/ece568/erss-hwk1-bh214/docker-deploy/web-app/uper/views.py changed, reloading.
Performing system checks...

System check identified no issues (0 silenced).
February 07, 2020 - 04:52:49
Django version 3.0.2, using settings 'mysite.settings'
Starting development server at http://0:8080/
Quit the server with CONTROL-C.
Watching for file changes with StatReloader
/home/ubuntu/ece568/erss-hwk1-bh214/docker-deploy/web-app/uper/views.py changed, reloading.
Performing system checks...

System check identified no issues (0 silenced).
February 07, 2020 - 04:52:54
Django version 3.0.2, using settings 'mysite.settings'
Starting development server at http://0:8000/
Quit the server with CONTROL-C.
Watching for file changes with StatReloader
/home/ubuntu/ece568/erss-hwk1-bh214/docker-deploy/web-app/uper/views.py changed, reloading.
Performing system checks...

System check identified no issues (0 silenced).
February 07, 2020 - 04:52:55
Django version 3.0.2, using settings 'mysite.settings'
Starting development server at http://0:8080/
Quit the server with CONTROL-C.
Watching for file changes with StatReloader
/home/ubuntu/ece568/erss-hwk1-bh214/docker-deploy/web-app/uper/views.py changed, reloading.
Performing system checks...

System check identified no issues (0 silenced).
February 07, 2020 - 04:53:03
Django version 3.0.2, using settings 'mysite.settings'
Starting development server at http://0:8000/
Quit the server with CONTROL-C.
Watching for file changes with StatReloader
/home/ubuntu/ece568/erss-hwk1-bh214/docker-deploy/web-app/uper/views.py changed, reloading.
Performing system checks...

System check identified no issues (0 silenced).
February 07, 2020 - 04:53:03
Django version 3.0.2, using settings 'mysite.settings'
Starting development server at http://0:8080/
Quit the server with CONTROL-C.
Watching for file changes with StatReloader
/home/ubuntu/ece568/erss-hwk1-bh214/docker-deploy/web-app/uper/views.py changed, reloading.
Performing system checks...

System check identified no issues (0 silenced).
February 07, 2020 - 04:57:59
Django version 3.0.2, using settings 'mysite.settings'
Starting development server at http://0:8080/
Quit the server with CONTROL-C.
Watching for file changes with StatReloader
/home/ubuntu/ece568/erss-hwk1-bh214/docker-deploy/web-app/uper/views.py changed, reloading.
Performing system checks...

System check identified no issues (0 silenced).
February 07, 2020 - 04:57:59
Django version 3.0.2, using settings 'mysite.settings'
Starting development server at http://0:8000/
Quit the server with CONTROL-C.
Watching for file changes with StatReloader
/home/ubuntu/ece568/erss-hwk1-bh214/docker-deploy/web-app/uper/views.py changed, reloading.
Performing system checks...

System check identified no issues (0 silenced).
February 07, 2020 - 04:59:31
Django version 3.0.2, using settings 'mysite.settings'
Starting development server at http://0:8000/
Quit the server with CONTROL-C.
Watching for file changes with StatReloader
/home/ubuntu/ece568/erss-hwk1-bh214/docker-deploy/web-app/uper/views.py changed, reloading.
Performing system checks...

System check identified no issues (0 silenced).
February 07, 2020 - 04:59:31
Django version 3.0.2, using settings 'mysite.settings'
Starting development server at http://0:8080/
Quit the server with CONTROL-C.
Watching for file changes with StatReloader
/home/ubuntu/ece568/erss-hwk1-bh214/docker-deploy/web-app/uper/views.py changed, reloading.
Performing system checks...

System check identified no issues (0 silenced).
February 07, 2020 - 04:59:54
Django version 3.0.2, using settings 'mysite.settings'
Starting development server at http://0:8000/
Quit the server with CONTROL-C.
Watching for file changes with StatReloader
/home/ubuntu/ece568/erss-hwk1-bh214/docker-deploy/web-app/uper/views.py changed, reloading.
Performing system checks...

System check identified no issues (0 silenced).
February 07, 2020 - 04:59:54
Django version 3.0.2, using settings 'mysite.settings'
Starting development server at http://0:8080/
Quit the server with CONTROL-C.
Watching for file changes with StatReloader
/home/ubuntu/ece568/erss-hwk1-bh214/docker-deploy/web-app/uper/views.py changed, reloading.
Performing system checks...

System check identified no issues (0 silenced).
February 07, 2020 - 05:01:04
Django version 3.0.2, using settings 'mysite.settings'
Starting development server at http://0:8000/
Quit the server with CONTROL-C.
Watching for file changes with StatReloader
/home/ubuntu/ece568/erss-hwk1-bh214/docker-deploy/web-app/uper/views.py changed, reloading.
Performing system checks...

System check identified no issues (0 silenced).
February 07, 2020 - 05:01:04
Django version 3.0.2, using settings 'mysite.settings'
Starting development server at http://0:8080/
Quit the server with CONTROL-C.
Watching for file changes with StatReloader
/home/ubuntu/ece568/erss-hwk1-bh214/docker-deploy/web-app/uper/views.py changed, reloading.
Performing system checks...

System check identified no issues (0 silenced).
February 07, 2020 - 05:01:41
Django version 3.0.2, using settings 'mysite.settings'
Starting development server at http://0:8080/
Quit the server with CONTROL-C.
Watching for file changes with StatReloader
/home/ubuntu/ece568/erss-hwk1-bh214/docker-deploy/web-app/uper/views.py changed, reloading.
Performing system checks...

System check identified no issues (0 silenced).
February 07, 2020 - 05:01:40
Django version 3.0.2, using settings 'mysite.settings'
Starting development server at http://0:8000/
Quit the server with CONTROL-C.
Watching for file changes with StatReloader
/home/ubuntu/ece568/erss-hwk1-bh214/docker-deploy/web-app/uper/views.py changed, reloading.
Performing system checks...

System check identified no issues (0 silenced).
February 07, 2020 - 05:01:51
Django version 3.0.2, using settings 'mysite.settings'
Starting development server at http://0:8080/
Quit the server with CONTROL-C.
Watching for file changes with StatReloader
/home/ubuntu/ece568/erss-hwk1-bh214/docker-deploy/web-app/uper/views.py changed, reloading.
Performing system checks...

System check identified no issues (0 silenced).
February 07, 2020 - 05:01:51
Django version 3.0.2, using settings 'mysite.settings'
Starting development server at http://0:8000/
Quit the server with CONTROL-C.
Watching for file changes with StatReloader
[07/Feb/2020 05:02:43] "GET /uper/driver_ride_search/ HTTP/1.1" 200 25
[07/Feb/2020 05:02:49] "POST /uper/logout/ HTTP/1.1" 302 0
[07/Feb/2020 05:02:49] "GET /uper/ HTTP/1.1" 200 543
[07/Feb/2020 05:02:50] "GET /uper/register/ HTTP/1.1" 200 525
[07/Feb/2020 05:02:57] "POST /uper/login/ HTTP/1.1" 302 0
[07/Feb/2020 05:02:57] "GET /uper/main_page/ HTTP/1.1" 200 2882
[07/Feb/2020 05:03:00] "GET /uper/driver_register/ HTTP/1.1" 200 782
[07/Feb/2020 05:03:27] "POST /uper/driver_register_process/ HTTP/1.1" 302 0
[07/Feb/2020 05:03:27] "GET /uper/main_page/ HTTP/1.1" 200 2882
[07/Feb/2020 05:03:29] "GET /uper/driver_ride_search/ HTTP/1.1" 200 17
[07/Feb/2020 05:03:32] "GET /uper/driver_ride_search/ HTTP/1.1" 200 17
[07/Feb/2020 05:03:34] "GET /uper/driver_ride_search/ HTTP/1.1" 200 17
[07/Feb/2020 05:03:35] "GET /uper/driver_ride_search/ HTTP/1.1" 200 17
[07/Feb/2020 05:03:37] "GET /uper/driver_ride_search/ HTTP/1.1" 200 17
[07/Feb/2020 05:03:38] "GET /uper/driver_ride_search/ HTTP/1.1" 200 17
[07/Feb/2020 05:03:40] "GET /uper/driver_ride_search/ HTTP/1.1" 200 17
[07/Feb/2020 05:05:39] "GET /uper/driver_ride_search/ HTTP/1.1" 200 17
[07/Feb/2020 05:05:45] "POST /uper/logout/ HTTP/1.1" 302 0
[07/Feb/2020 05:05:45] "GET /uper/ HTTP/1.1" 200 543
[07/Feb/2020 05:05:52] "POST /uper/login/ HTTP/1.1" 302 0
[07/Feb/2020 05:05:53] "GET /uper/main_page/ HTTP/1.1" 200 3853
[07/Feb/2020 05:06:04] "POST /uper/logout/ HTTP/1.1" 302 0
[07/Feb/2020 05:06:04] "GET /uper/ HTTP/1.1" 200 543
[07/Feb/2020 05:06:08] "POST /uper/login/ HTTP/1.1" 200 27
[07/Feb/2020 05:06:13] "POST /uper/login/ HTTP/1.1" 302 0
[07/Feb/2020 05:06:13] "GET /uper/main_page/ HTTP/1.1" 200 2882
[07/Feb/2020 05:06:17] "GET /uper/edit_driver/ HTTP/1.1" 200 725
[07/Feb/2020 05:06:32] "POST /uper/edit_driver_process/ HTTP/1.1" 302 0
[07/Feb/2020 05:06:32] "GET /uper/main_page/ HTTP/1.1" 200 2882
[07/Feb/2020 05:06:33] "GET /uper/driver_ride_search/ HTTP/1.1" 200 1132
/usr/local/lib/python3.6/dist-packages/django/db/models/fields/__init__.py:1364: RuntimeWarning: DateTimeField Personal_ride.called_time received a naive datetime (2020-02-07 05:06:39.224950) while time zone support is active.
  RuntimeWarning)
[07/Feb/2020 05:06:39] "POST /uper/take_order/ HTTP/1.1" 302 0
[07/Feb/2020 05:06:39] "GET /uper/main_page/ HTTP/1.1" 200 2882
/home/ubuntu/ece568/erss-hwk1-bh214/docker-deploy/web-app/uper/views.py changed, reloading.
Performing system checks...

System check identified no issues (0 silenced).
February 07, 2020 - 05:01:57
Django version 3.0.2, using settings 'mysite.settings'
Starting development server at http://0:8080/
Quit the server with CONTROL-C.
Watching for file changes with StatReloader
/home/ubuntu/ece568/erss-hwk1-bh214/docker-deploy/web-app/uper/views.py changed, reloading.
Performing system checks...

System check identified no issues (0 silenced).
February 07, 2020 - 05:01:58
Django version 3.0.2, using settings 'mysite.settings'
Starting development server at http://0:8000/
Quit the server with CONTROL-C.
Watching for file changes with StatReloader
/home/ubuntu/ece568/erss-hwk1-bh214/docker-deploy/web-app/uper/views.py changed, reloading.
Performing system checks...

System check identified no issues (0 silenced).
February 07, 2020 - 05:09:38
Django version 3.0.2, using settings 'mysite.settings'
Starting development server at http://0:8080/
Quit the server with CONTROL-C.
Watching for file changes with StatReloader
/home/ubuntu/ece568/erss-hwk1-bh214/docker-deploy/web-app/uper/views.py changed, reloading.
Performing system checks...

System check identified no issues (0 silenced).
February 07, 2020 - 05:09:39
Django version 3.0.2, using settings 'mysite.settings'
Starting development server at http://0:8000/
Quit the server with CONTROL-C.
Watching for file changes with StatReloader
[07/Feb/2020 05:09:55] "GET /uper/driver_ride_search/ HTTP/1.1" 200 649
/usr/local/lib/python3.6/dist-packages/django/db/models/fields/__init__.py:1364: RuntimeWarning: DateTimeField Personal_ride.called_time received a naive datetime (2020-02-07 05:09:57.127731) while time zone support is active.
  RuntimeWarning)
[07/Feb/2020 05:09:57] "POST /uper/take_order/ HTTP/1.1" 302 0
[07/Feb/2020 05:09:57] "GET /uper/main_page/ HTTP/1.1" 200 2882
[07/Feb/2020 05:14:15] "GET /uper/main_page/ HTTP/1.1" 200 2882
[07/Feb/2020 05:25:32] "GET /uper/driver_ride_search/ HTTP/1.1" 200 17
[07/Feb/2020 05:25:37] "POST /uper/logout/ HTTP/1.1" 302 0
[07/Feb/2020 05:25:38] "GET /uper/ HTTP/1.1" 200 543
[07/Feb/2020 05:25:39] "GET /uper/register/ HTTP/1.1" 200 525
[07/Feb/2020 05:25:55] "POST /uper/login/ HTTP/1.1" 302 0
[07/Feb/2020 05:25:55] "GET /uper/main_page/ HTTP/1.1" 200 2881
[07/Feb/2020 05:25:58] "GET /uper/request_ride/ HTTP/1.1" 200 2799
/usr/local/lib/python3.6/dist-packages/django/db/models/fields/__init__.py:1364: RuntimeWarning: DateTimeField Personal_ride.called_time received a naive datetime (2020-02-07 05:26:16.292268) while time zone support is active.
  RuntimeWarning)
/usr/local/lib/python3.6/dist-packages/django/db/models/fields/__init__.py:1364: RuntimeWarning: DateTimeField Ride.arrival_datetime received a naive datetime (1121-12-12 00:12:00) while time zone support is active.
  RuntimeWarning)
[07/Feb/2020 05:26:16] "POST /uper/request_or_edit_ride_process/ HTTP/1.1" 302 0
[07/Feb/2020 05:26:16] "GET /uper/main_page/ HTTP/1.1" 200 3854
[07/Feb/2020 05:26:17] "POST /uper/logout/ HTTP/1.1" 302 0
[07/Feb/2020 05:26:17] "GET /uper/ HTTP/1.1" 200 543
[07/Feb/2020 05:26:27] "POST /uper/login/ HTTP/1.1" 302 0
[07/Feb/2020 05:26:27] "GET /uper/main_page/ HTTP/1.1" 200 2882
[07/Feb/2020 05:26:29] "GET /uper/driver_ride_search/ HTTP/1.1" 200 653
/home/ubuntu/ece568/erss-hwk1-bh214/docker-deploy/web-app/uper/views.py changed, reloading.
Performing system checks...

System check identified no issues (0 silenced).
February 07, 2020 - 05:09:41
Django version 3.0.2, using settings 'mysite.settings'
Starting development server at http://0:8000/
Quit the server with CONTROL-C.
/home/ubuntu/ece568/erss-hwk1-bh214/docker-deploy/web-app/uper/views.py changed, reloading.
Performing system checks...

System check identified no issues (0 silenced).
February 07, 2020 - 05:09:40
Django version 3.0.2, using settings 'mysite.settings'
Starting development server at http://0:8080/
Quit the server with CONTROL-C.
Watching for file changes with StatReloader
Watching for file changes with StatReloader
/usr/local/lib/python3.6/dist-packages/django/db/models/fields/__init__.py:1364: RuntimeWarning: DateTimeField Personal_ride.called_time received a naive datetime (2020-02-07 05:29:09.960061) while time zone support is active.
  RuntimeWarning)
[07/Feb/2020 05:29:09] "POST /uper/take_order/ HTTP/1.1" 302 0
[07/Feb/2020 05:29:10] "GET /uper/main_page/ HTTP/1.1" 200 2882
Watching for file changes with StatReloader
/home/ubuntu/ece568/erss-hwk1-bh214/docker-deploy/web-app/uper/views.py changed, reloading.
Performing system checks...

System check identified no issues (0 silenced).
February 07, 2020 - 05:29:06
Django version 3.0.2, using settings 'mysite.settings'
Starting development server at http://0:8000/
Quit the server with CONTROL-C.
/home/ubuntu/ece568/erss-hwk1-bh214/docker-deploy/web-app/uper/views.py changed, reloading.
Performing system checks...

System check identified no issues (0 silenced).
February 07, 2020 - 05:35:23
Django version 3.0.2, using settings 'mysite.settings'
Starting development server at http://0:8080/
Quit the server with CONTROL-C.
Watching for file changes with StatReloader
Watching for file changes with StatReloader
Internal Server Error: /uper/main_page/
Traceback (most recent call last):
  File "/usr/local/lib/python3.6/dist-packages/django/core/handlers/exception.py", line 34, in inner
    response = get_response(request)
  File "/usr/local/lib/python3.6/dist-packages/django/core/handlers/base.py", line 115, in _get_response
    response = self.process_exception_by_middleware(e, request)
  File "/usr/local/lib/python3.6/dist-packages/django/core/handlers/base.py", line 113, in _get_response
    response = wrapped_callback(request, *callback_args, **callback_kwargs)
  File "/home/ubuntu/ece568/erss-hwk1-bh214/docker-deploy/web-app/uper/views.py", line 57, in main_page
    return render(request, 'uper/main_page.html', context)
  File "/usr/local/lib/python3.6/dist-packages/django/shortcuts.py", line 19, in render
    content = loader.render_to_string(template_name, context, request, using=using)
  File "/usr/local/lib/python3.6/dist-packages/django/template/loader.py", line 61, in render_to_string
    template = get_template(template_name, using=using)
  File "/usr/local/lib/python3.6/dist-packages/django/template/loader.py", line 15, in get_template
    return engine.get_template(template_name)
  File "/usr/local/lib/python3.6/dist-packages/django/template/backends/django.py", line 34, in get_template
    return Template(self.engine.get_template(template_name), self)
  File "/usr/local/lib/python3.6/dist-packages/django/template/engine.py", line 143, in get_template
    template, origin = self.find_template(template_name)
  File "/usr/local/lib/python3.6/dist-packages/django/template/engine.py", line 125, in find_template
    template = loader.get_template(name, skip=skip)
  File "/usr/local/lib/python3.6/dist-packages/django/template/loaders/base.py", line 30, in get_template
    contents, origin, origin.template_name, self.engine,
  File "/usr/local/lib/python3.6/dist-packages/django/template/base.py", line 156, in __init__
    self.nodelist = self.compile_nodelist()
  File "/usr/local/lib/python3.6/dist-packages/django/template/base.py", line 194, in compile_nodelist
    return parser.parse()
  File "/usr/local/lib/python3.6/dist-packages/django/template/base.py", line 477, in parse
    raise self.error(token, e)
  File "/usr/local/lib/python3.6/dist-packages/django/template/base.py", line 475, in parse
    compiled_result = compile_func(self, token)
  File "/usr/local/lib/python3.6/dist-packages/django/template/defaulttags.py", line 795, in do_for
    " words: %s" % token.contents)
django.template.exceptions.TemplateSyntaxError: 'for' statements should have at least four words: for personal
[07/Feb/2020 05:36:08] "GET /uper/main_page/ HTTP/1.1" 500 142437
[07/Feb/2020 05:36:36] "GET /uper/main_page/ HTTP/1.1" 200 5880
Internal Server Error: /uper/edit_ride/
Traceback (most recent call last):
  File "/usr/local/lib/python3.6/dist-packages/django/core/handlers/exception.py", line 34, in inner
    response = get_response(request)
  File "/usr/local/lib/python3.6/dist-packages/django/core/handlers/base.py", line 115, in _get_response
    response = self.process_exception_by_middleware(e, request)
  File "/usr/local/lib/python3.6/dist-packages/django/core/handlers/base.py", line 113, in _get_response
    response = wrapped_callback(request, *callback_args, **callback_kwargs)
  File "/home/ubuntu/ece568/erss-hwk1-bh214/docker-deploy/web-app/uper/views.py", line 87, in edit_ride
    return HttpRequestRedirect(reverse('uper:main_page'))
NameError: name 'HttpRequestRedirect' is not defined
[07/Feb/2020 05:36:42] "POST /uper/edit_ride/ HTTP/1.1" 500 66076
[07/Feb/2020 05:38:23] "GET /uper/main_page/ HTTP/1.1" 200 4826
[07/Feb/2020 05:39:22] "GET /uper/main_page/ HTTP/1.1" 200 4826
Internal Server Error: /uper/main_page/
Traceback (most recent call last):
  File "/usr/local/lib/python3.6/dist-packages/django/core/handlers/exception.py", line 34, in inner
    response = get_response(request)
  File "/usr/local/lib/python3.6/dist-packages/django/core/handlers/base.py", line 115, in _get_response
    response = self.process_exception_by_middleware(e, request)
  File "/usr/local/lib/python3.6/dist-packages/django/core/handlers/base.py", line 113, in _get_response
    response = wrapped_callback(request, *callback_args, **callback_kwargs)
  File "/home/ubuntu/ece568/erss-hwk1-bh214/docker-deploy/web-app/uper/views.py", line 57, in main_page
    return render(request, 'uper/main_page.html', context)
  File "/usr/local/lib/python3.6/dist-packages/django/shortcuts.py", line 19, in render
    content = loader.render_to_string(template_name, context, request, using=using)
  File "/usr/local/lib/python3.6/dist-packages/django/template/loader.py", line 62, in render_to_string
    return template.render(context, request)
  File "/usr/local/lib/python3.6/dist-packages/django/template/backends/django.py", line 61, in render
    return self.template.render(context)
  File "/usr/local/lib/python3.6/dist-packages/django/template/base.py", line 171, in render
    return self._render(context)
  File "/usr/local/lib/python3.6/dist-packages/django/template/base.py", line 163, in _render
    return self.nodelist.render(context)
  File "/usr/local/lib/python3.6/dist-packages/django/template/base.py", line 936, in render
    bit = node.render_annotated(context)
  File "/usr/local/lib/python3.6/dist-packages/django/template/base.py", line 903, in render_annotated
    return self.render(context)
  File "/usr/local/lib/python3.6/dist-packages/django/template/defaulttags.py", line 209, in render
    nodelist.append(node.render_annotated(context))
  File "/usr/local/lib/python3.6/dist-packages/django/template/base.py", line 903, in render_annotated
    return self.render(context)
  File "/usr/local/lib/python3.6/dist-packages/django/template/defaulttags.py", line 309, in render
    return nodelist.render(context)
  File "/usr/local/lib/python3.6/dist-packages/django/template/base.py", line 936, in render
    bit = node.render_annotated(context)
  File "/usr/local/lib/python3.6/dist-packages/django/template/base.py", line 903, in render_annotated
    return self.render(context)
  File "/usr/local/lib/python3.6/dist-packages/django/template/defaulttags.py", line 209, in render
    nodelist.append(node.render_annotated(context))
  File "/usr/local/lib/python3.6/dist-packages/django/template/base.py", line 903, in render_annotated
    return self.render(context)
  File "/usr/local/lib/python3.6/dist-packages/django/template/defaulttags.py", line 309, in render
    return nodelist.render(context)
  File "/usr/local/lib/python3.6/dist-packages/django/template/base.py", line 936, in render
    bit = node.render_annotated(context)
  File "/usr/local/lib/python3.6/dist-packages/django/template/base.py", line 903, in render_annotated
    return self.render(context)
  File "/usr/local/lib/python3.6/dist-packages/django/template/defaulttags.py", line 165, in render
    values = list(values)
TypeError: 'RelatedManager' object is not iterable
[07/Feb/2020 05:41:39] "GET /uper/main_page/ HTTP/1.1" 500 169463
Internal Server Error: /uper/main_page/
Traceback (most recent call last):
  File "/usr/local/lib/python3.6/dist-packages/django/core/handlers/exception.py", line 34, in inner
    response = get_response(request)
  File "/usr/local/lib/python3.6/dist-packages/django/core/handlers/base.py", line 115, in _get_response
    response = self.process_exception_by_middleware(e, request)
  File "/usr/local/lib/python3.6/dist-packages/django/core/handlers/base.py", line 113, in _get_response
    response = wrapped_callback(request, *callback_args, **callback_kwargs)
  File "/home/ubuntu/ece568/erss-hwk1-bh214/docker-deploy/web-app/uper/views.py", line 57, in main_page
    return render(request, 'uper/main_page.html', context)
  File "/usr/local/lib/python3.6/dist-packages/django/shortcuts.py", line 19, in render
    content = loader.render_to_string(template_name, context, request, using=using)
  File "/usr/local/lib/python3.6/dist-packages/django/template/loader.py", line 61, in render_to_string
    template = get_template(template_name, using=using)
  File "/usr/local/lib/python3.6/dist-packages/django/template/loader.py", line 15, in get_template
    return engine.get_template(template_name)
  File "/usr/local/lib/python3.6/dist-packages/django/template/backends/django.py", line 34, in get_template
    return Template(self.engine.get_template(template_name), self)
  File "/usr/local/lib/python3.6/dist-packages/django/template/engine.py", line 143, in get_template
    template, origin = self.find_template(template_name)
  File "/usr/local/lib/python3.6/dist-packages/django/template/engine.py", line 125, in find_template
    template = loader.get_template(name, skip=skip)
  File "/usr/local/lib/python3.6/dist-packages/django/template/loaders/base.py", line 30, in get_template
    contents, origin, origin.template_name, self.engine,
  File "/usr/local/lib/python3.6/dist-packages/django/template/base.py", line 156, in __init__
    self.nodelist = self.compile_nodelist()
  File "/usr/local/lib/python3.6/dist-packages/django/template/base.py", line 194, in compile_nodelist
    return parser.parse()
  File "/usr/local/lib/python3.6/dist-packages/django/template/base.py", line 477, in parse
    raise self.error(token, e)
  File "/usr/local/lib/python3.6/dist-packages/django/template/base.py", line 475, in parse
    compiled_result = compile_func(self, token)
  File "/usr/local/lib/python3.6/dist-packages/django/template/defaulttags.py", line 811, in do_for
    nodelist_loop = parser.parse(('empty', 'endfor',))
  File "/usr/local/lib/python3.6/dist-packages/django/template/base.py", line 477, in parse
    raise self.error(token, e)
  File "/usr/local/lib/python3.6/dist-packages/django/template/base.py", line 475, in parse
    compiled_result = compile_func(self, token)
  File "/usr/local/lib/python3.6/dist-packages/django/template/defaulttags.py", line 952, in do_if
    nodelist = parser.parse(('elif', 'else', 'endif'))
  File "/usr/local/lib/python3.6/dist-packages/django/template/base.py", line 477, in parse
    raise self.error(token, e)
  File "/usr/local/lib/python3.6/dist-packages/django/template/base.py", line 475, in parse
    compiled_result = compile_func(self, token)
  File "/usr/local/lib/python3.6/dist-packages/django/template/defaulttags.py", line 811, in do_for
    nodelist_loop = parser.parse(('empty', 'endfor',))
  File "/usr/local/lib/python3.6/dist-packages/django/template/base.py", line 477, in parse
    raise self.error(token, e)
  File "/usr/local/lib/python3.6/dist-packages/django/template/base.py", line 475, in parse
    compiled_result = compile_func(self, token)
  File "/usr/local/lib/python3.6/dist-packages/django/template/defaulttags.py", line 966, in do_if
    nodelist = parser.parse(('endif',))
  File "/usr/local/lib/python3.6/dist-packages/django/template/base.py", line 477, in parse
    raise self.error(token, e)
  File "/usr/local/lib/python3.6/dist-packages/django/template/base.py", line 475, in parse
    compiled_result = compile_func(self, token)
  File "/usr/local/lib/python3.6/dist-packages/django/template/defaulttags.py", line 810, in do_for
    sequence = parser.compile_filter(bits[in_index + 1])
  File "/usr/local/lib/python3.6/dist-packages/django/template/base.py", line 562, in compile_filter
    return FilterExpression(token, self)
  File "/usr/local/lib/python3.6/dist-packages/django/template/base.py", line 662, in __init__
    "from '%s'" % (token[upto:], token))
django.template.exceptions.TemplateSyntaxError: Could not parse the remainder: '()' from 'personal_ride.ride.personal_ride_set.all()'
[07/Feb/2020 05:42:21] "GET /uper/main_page/ HTTP/1.1" 500 221720
Internal Server Error: /uper/edit_ride/
Traceback (most recent call last):
  File "/usr/local/lib/python3.6/dist-packages/django/core/handlers/exception.py", line 34, in inner
    response = get_response(request)
  File "/usr/local/lib/python3.6/dist-packages/django/core/handlers/base.py", line 115, in _get_response
    response = self.process_exception_by_middleware(e, request)
  File "/usr/local/lib/python3.6/dist-packages/django/core/handlers/base.py", line 113, in _get_response
    response = wrapped_callback(request, *callback_args, **callback_kwargs)
  File "/home/ubuntu/ece568/erss-hwk1-bh214/docker-deploy/web-app/uper/views.py", line 79, in edit_ride
    personal_ride = Personal_ride.objects.get(pk = request.POST['personal_ride_id'])
  File "/usr/local/lib/python3.6/dist-packages/django/db/models/manager.py", line 82, in manager_method
    return getattr(self.get_queryset(), name)(*args, **kwargs)
  File "/usr/local/lib/python3.6/dist-packages/django/db/models/query.py", line 417, in get
    self.model._meta.object_name
uper.models.Personal_ride.DoesNotExist: Personal_ride matching query does not exist.
[07/Feb/2020 05:42:30] "POST /uper/edit_ride/ HTTP/1.1" 500 75439
Internal Server Error: /uper/edit_ride/
Traceback (most recent call last):
  File "/usr/local/lib/python3.6/dist-packages/django/core/handlers/exception.py", line 34, in inner
    response = get_response(request)
  File "/usr/local/lib/python3.6/dist-packages/django/core/handlers/base.py", line 115, in _get_response
    response = self.process_exception_by_middleware(e, request)
  File "/usr/local/lib/python3.6/dist-packages/django/core/handlers/base.py", line 113, in _get_response
    response = wrapped_callback(request, *callback_args, **callback_kwargs)
  File "/home/ubuntu/ece568/erss-hwk1-bh214/docker-deploy/web-app/uper/views.py", line 79, in edit_ride
    personal_ride = Personal_ride.objects.get(pk = request.POST['personal_ride_id'])
  File "/usr/local/lib/python3.6/dist-packages/django/db/models/manager.py", line 82, in manager_method
    return getattr(self.get_queryset(), name)(*args, **kwargs)
  File "/usr/local/lib/python3.6/dist-packages/django/db/models/query.py", line 417, in get
    self.model._meta.object_name
uper.models.Personal_ride.DoesNotExist: Personal_ride matching query does not exist.
[07/Feb/2020 05:42:32] "POST /uper/edit_ride/ HTTP/1.1" 500 75439
Internal Server Error: /uper/edit_ride/
Traceback (most recent call last):
  File "/usr/local/lib/python3.6/dist-packages/django/core/handlers/exception.py", line 34, in inner
    response = get_response(request)
  File "/usr/local/lib/python3.6/dist-packages/django/core/handlers/base.py", line 115, in _get_response
    response = self.process_exception_by_middleware(e, request)
  File "/usr/local/lib/python3.6/dist-packages/django/core/handlers/base.py", line 113, in _get_response
    response = wrapped_callback(request, *callback_args, **callback_kwargs)
  File "/home/ubuntu/ece568/erss-hwk1-bh214/docker-deploy/web-app/uper/views.py", line 79, in edit_ride
    personal_ride = Personal_ride.objects.get(pk = request.POST['personal_ride_id'])
  File "/usr/local/lib/python3.6/dist-packages/django/db/models/manager.py", line 82, in manager_method
    return getattr(self.get_queryset(), name)(*args, **kwargs)
  File "/usr/local/lib/python3.6/dist-packages/django/db/models/query.py", line 417, in get
    self.model._meta.object_name
uper.models.Personal_ride.DoesNotExist: Personal_ride matching query does not exist.
[07/Feb/2020 05:44:31] "POST /uper/edit_ride/ HTTP/1.1" 500 75439
[07/Feb/2020 05:44:35] "GET /uper/ HTTP/1.1" 200 543
[07/Feb/2020 05:44:45] "POST /uper/login/ HTTP/1.1" 302 0
[07/Feb/2020 05:44:45] "GET /uper/main_page/ HTTP/1.1" 200 5272
[07/Feb/2020 05:46:27] "GET /uper/main_page/ HTTP/1.1" 200 4826
[07/Feb/2020 05:59:39] "GET /uper/main_page/ HTTP/1.1" 200 5655
[07/Feb/2020 06:01:13] "GET /uper/main_page/ HTTP/1.1" 200 5281
[07/Feb/2020 06:06:06] "GET /uper/main_page/ HTTP/1.1" 200 5585
[07/Feb/2020 06:07:18] "GET /uper/main_page/ HTTP/1.1" 200 5199
Not Found: /
[07/Feb/2020 06:10:12] "GET / HTTP/1.1" 404 2031
/home/ubuntu/ece568/erss-hwk1-bh214/docker-deploy/web-app/uper/views.py changed, reloading.
Performing system checks...

System check identified no issues (0 silenced).
February 07, 2020 - 05:36:04
Django version 3.0.2, using settings 'mysite.settings'
Starting development server at http://0:8000/
Quit the server with CONTROL-C.
/home/ubuntu/ece568/erss-hwk1-bh214/docker-deploy/web-app/uper/views.py changed, reloading.
Performing system checks...

System check identified no issues (0 silenced).
February 07, 2020 - 05:36:04
Django version 3.0.2, using settings 'mysite.settings'
Starting development server at http://0:8080/
Quit the server with CONTROL-C.
Watching for file changes with StatReloader
Watching for file changes with StatReloader
/home/ubuntu/ece568/erss-hwk1-bh214/docker-deploy/web-app/uper/views.py changed, reloading.
Performing system checks...

System check identified no issues (0 silenced).
February 07, 2020 - 06:10:57
Django version 3.0.2, using settings 'mysite.settings'
Starting development server at http://0:8000/
Quit the server with CONTROL-C.
/home/ubuntu/ece568/erss-hwk1-bh214/docker-deploy/web-app/uper/views.py changed, reloading.
Performing system checks...

System check identified no issues (0 silenced).
February 07, 2020 - 06:10:57
Django version 3.0.2, using settings 'mysite.settings'
Starting development server at http://0:8080/
Quit the server with CONTROL-C.
Watching for file changes with StatReloader
Watching for file changes with StatReloader
/home/ubuntu/ece568/erss-hwk1-bh214/docker-deploy/web-app/uper/views.py changed, reloading.
Performing system checks...

System check identified no issues (0 silenced).
February 07, 2020 - 06:15:33
Django version 3.0.2, using settings 'mysite.settings'
Starting development server at http://0:8080/
Quit the server with CONTROL-C.
/home/ubuntu/ece568/erss-hwk1-bh214/docker-deploy/web-app/uper/views.py changed, reloading.
Performing system checks...

System check identified no issues (0 silenced).
February 07, 2020 - 06:15:33
Django version 3.0.2, using settings 'mysite.settings'
Starting development server at http://0:8000/
Quit the server with CONTROL-C.
Watching for file changes with StatReloader
Watching for file changes with StatReloader
/home/ubuntu/ece568/erss-hwk1-bh214/docker-deploy/web-app/uper/views.py changed, reloading.
Performing system checks...

System check identified no issues (0 silenced).
February 07, 2020 - 06:15:40
Django version 3.0.2, using settings 'mysite.settings'
Starting development server at http://0:8080/
Quit the server with CONTROL-C.
/home/ubuntu/ece568/erss-hwk1-bh214/docker-deploy/web-app/uper/views.py changed, reloading.
Performing system checks...

System check identified no issues (0 silenced).
February 07, 2020 - 06:15:40
Django version 3.0.2, using settings 'mysite.settings'
Starting development server at http://0:8000/
Quit the server with CONTROL-C.
Watching for file changes with StatReloader
Watching for file changes with StatReloader
/home/ubuntu/ece568/erss-hwk1-bh214/docker-deploy/web-app/uper/views.py changed, reloading.
Performing system checks...

System check identified no issues (0 silenced).
February 07, 2020 - 06:15:42
Django version 3.0.2, using settings 'mysite.settings'
Starting development server at http://0:8080/
Quit the server with CONTROL-C.
/home/ubuntu/ece568/erss-hwk1-bh214/docker-deploy/web-app/uper/views.py changed, reloading.
Performing system checks...

System check identified no issues (0 silenced).
February 07, 2020 - 06:15:42
Django version 3.0.2, using settings 'mysite.settings'
Starting development server at http://0:8000/
Quit the server with CONTROL-C.
Watching for file changes with StatReloader
Watching for file changes with StatReloader
/home/ubuntu/ece568/erss-hwk1-bh214/docker-deploy/web-app/uper/views.py changed, reloading.
Performing system checks...

System check identified no issues (0 silenced).
February 07, 2020 - 06:15:50
Django version 3.0.2, using settings 'mysite.settings'
Starting development server at http://0:8080/
Quit the server with CONTROL-C.
/home/ubuntu/ece568/erss-hwk1-bh214/docker-deploy/web-app/uper/views.py changed, reloading.
Performing system checks...

System check identified no issues (0 silenced).
February 07, 2020 - 06:15:50
Django version 3.0.2, using settings 'mysite.settings'
Starting development server at http://0:8000/
Quit the server with CONTROL-C.
Watching for file changes with StatReloader
Watching for file changes with StatReloader
/home/ubuntu/ece568/erss-hwk1-bh214/docker-deploy/web-app/uper/views.py changed, reloading.
Performing system checks...

System check identified no issues (0 silenced).
February 07, 2020 - 06:16:08
Django version 3.0.2, using settings 'mysite.settings'
Starting development server at http://0:8080/
Quit the server with CONTROL-C.
/home/ubuntu/ece568/erss-hwk1-bh214/docker-deploy/web-app/uper/views.py changed, reloading.
Performing system checks...

System check identified no issues (0 silenced).
February 07, 2020 - 06:16:08
Django version 3.0.2, using settings 'mysite.settings'
Starting development server at http://0:8000/
Quit the server with CONTROL-C.
Watching for file changes with StatReloader
Watching for file changes with StatReloader
/home/ubuntu/ece568/erss-hwk1-bh214/docker-deploy/web-app/uper/views.py changed, reloading.
Performing system checks...

System check identified no issues (0 silenced).
February 07, 2020 - 06:16:24
Django version 3.0.2, using settings 'mysite.settings'
Starting development server at http://0:8080/
Quit the server with CONTROL-C.
/home/ubuntu/ece568/erss-hwk1-bh214/docker-deploy/web-app/uper/views.py changed, reloading.
Performing system checks...

System check identified no issues (0 silenced).
February 07, 2020 - 06:16:24
Django version 3.0.2, using settings 'mysite.settings'
Starting development server at http://0:8000/
Quit the server with CONTROL-C.
Watching for file changes with StatReloader
Watching for file changes with StatReloader
/home/ubuntu/ece568/erss-hwk1-bh214/docker-deploy/web-app/uper/views.py changed, reloading.
Performing system checks...

System check identified no issues (0 silenced).
February 07, 2020 - 06:16:37
Django version 3.0.2, using settings 'mysite.settings'
Starting development server at http://0:8080/
Quit the server with CONTROL-C.
/home/ubuntu/ece568/erss-hwk1-bh214/docker-deploy/web-app/uper/views.py changed, reloading.
Performing system checks...

System check identified no issues (0 silenced).
February 07, 2020 - 06:16:37
Django version 3.0.2, using settings 'mysite.settings'
Starting development server at http://0:8000/
Quit the server with CONTROL-C.
Watching for file changes with StatReloader
Watching for file changes with StatReloader
/home/ubuntu/ece568/erss-hwk1-bh214/docker-deploy/web-app/mysite/settings.py changed, reloading.
Performing system checks...

System check identified no issues (0 silenced).
February 07, 2020 - 06:16:43
Django version 3.0.2, using settings 'mysite.settings'
Starting development server at http://0:8080/
Quit the server with CONTROL-C.
/home/ubuntu/ece568/erss-hwk1-bh214/docker-deploy/web-app/mysite/settings.py changed, reloading.
Performing system checks...

System check identified no issues (0 silenced).
February 07, 2020 - 06:16:43
Django version 3.0.2, using settings 'mysite.settings'
Starting development server at http://0:8000/
Quit the server with CONTROL-C.
Watching for file changes with StatReloader
Watching for file changes with StatReloader
/home/ubuntu/ece568/erss-hwk1-bh214/docker-deploy/web-app/mysite/settings.py changed, reloading.
Performing system checks...

System check identified no issues (0 silenced).
February 07, 2020 - 06:18:00
Django version 3.0.2, using settings 'mysite.settings'
Starting development server at http://0:8080/
Quit the server with CONTROL-C.
/home/ubuntu/ece568/erss-hwk1-bh214/docker-deploy/web-app/mysite/settings.py changed, reloading.
Performing system checks...

System check identified no issues (0 silenced).
February 07, 2020 - 06:18:00
Django version 3.0.2, using settings 'mysite.settings'
Starting development server at http://0:8000/
Quit the server with CONTROL-C.
Watching for file changes with StatReloader
Watching for file changes with StatReloader
/home/ubuntu/ece568/erss-hwk1-bh214/docker-deploy/web-app/mysite/settings.py changed, reloading.
Performing system checks...

System check identified no issues (0 silenced).
February 07, 2020 - 06:18:03
Django version 3.0.2, using settings 'mysite.settings'
Starting development server at http://0:8000/
Quit the server with CONTROL-C.
/home/ubuntu/ece568/erss-hwk1-bh214/docker-deploy/web-app/mysite/settings.py changed, reloading.
Performing system checks...

System check identified no issues (0 silenced).
February 07, 2020 - 06:18:03
Django version 3.0.2, using settings 'mysite.settings'
Starting development server at http://0:8080/
Quit the server with CONTROL-C.
Watching for file changes with StatReloader
Watching for file changes with StatReloader
/home/ubuntu/ece568/erss-hwk1-bh214/docker-deploy/web-app/mysite/settings.py changed, reloading.
Performing system checks...

System check identified no issues (0 silenced).
February 07, 2020 - 06:21:46
Django version 3.0.2, using settings 'mysite.settings'
Starting development server at http://0:8000/
Quit the server with CONTROL-C.
/home/ubuntu/ece568/erss-hwk1-bh214/docker-deploy/web-app/mysite/settings.py changed, reloading.
Performing system checks...

System check identified no issues (0 silenced).
February 07, 2020 - 06:21:46
Django version 3.0.2, using settings 'mysite.settings'
Starting development server at http://0:8080/
Quit the server with CONTROL-C.
Watching for file changes with StatReloader
Watching for file changes with StatReloader
/home/ubuntu/ece568/erss-hwk1-bh214/docker-deploy/web-app/mysite/settings.py changed, reloading.
Performing system checks...

System check identified no issues (0 silenced).
February 07, 2020 - 06:22:06
Django version 3.0.2, using settings 'mysite.settings'
Starting development server at http://0:8080/
Quit the server with CONTROL-C.
/home/ubuntu/ece568/erss-hwk1-bh214/docker-deploy/web-app/mysite/settings.py changed, reloading.
Performing system checks...

System check identified no issues (0 silenced).
February 07, 2020 - 06:22:06
Django version 3.0.2, using settings 'mysite.settings'
Starting development server at http://0:8000/
Quit the server with CONTROL-C.
Watching for file changes with StatReloader
Watching for file changes with StatReloader
/home/ubuntu/ece568/erss-hwk1-bh214/docker-deploy/web-app/mysite/settings.py changed, reloading.
Performing system checks...

System check identified no issues (0 silenced).
February 07, 2020 - 06:22:17
Django version 3.0.2, using settings 'mysite.settings'
Starting development server at http://0:8000/
Quit the server with CONTROL-C.
/home/ubuntu/ece568/erss-hwk1-bh214/docker-deploy/web-app/mysite/settings.py changed, reloading.
Performing system checks...

System check identified no issues (0 silenced).
February 07, 2020 - 06:22:17
Django version 3.0.2, using settings 'mysite.settings'
Starting development server at http://0:8080/
Quit the server with CONTROL-C.
Watching for file changes with StatReloader
Watching for file changes with StatReloader
/home/ubuntu/ece568/erss-hwk1-bh214/docker-deploy/web-app/mysite/settings.py changed, reloading.
Performing system checks...

System check identified no issues (0 silenced).
February 07, 2020 - 06:23:16
Django version 3.0.2, using settings 'mysite.settings'
Starting development server at http://0:8000/
Quit the server with CONTROL-C.
/home/ubuntu/ece568/erss-hwk1-bh214/docker-deploy/web-app/mysite/settings.py changed, reloading.
Performing system checks...

System check identified no issues (0 silenced).
February 07, 2020 - 06:23:16
Django version 3.0.2, using settings 'mysite.settings'
Starting development server at http://0:8080/
Quit the server with CONTROL-C.
Watching for file changes with StatReloader
Watching for file changes with StatReloader
/home/ubuntu/ece568/erss-hwk1-bh214/docker-deploy/web-app/uper/views.py changed, reloading.
Performing system checks...

System check identified no issues (0 silenced).
February 07, 2020 - 06:24:05
Django version 3.0.2, using settings 'mysite.settings'
Starting development server at http://0:8000/
Quit the server with CONTROL-C.
/home/ubuntu/ece568/erss-hwk1-bh214/docker-deploy/web-app/uper/views.py changed, reloading.
Performing system checks...

System check identified no issues (0 silenced).
February 07, 2020 - 06:24:05
Django version 3.0.2, using settings 'mysite.settings'
Starting development server at http://0:8080/
Quit the server with CONTROL-C.
Watching for file changes with StatReloader
Watching for file changes with StatReloader
/home/ubuntu/ece568/erss-hwk1-bh214/docker-deploy/web-app/uper/views.py changed, reloading.
Performing system checks...

System check identified no issues (0 silenced).
February 07, 2020 - 06:24:57
Django version 3.0.2, using settings 'mysite.settings'
Starting development server at http://0:8080/
Quit the server with CONTROL-C.
/home/ubuntu/ece568/erss-hwk1-bh214/docker-deploy/web-app/uper/views.py changed, reloading.
Performing system checks...

System check identified no issues (0 silenced).
February 07, 2020 - 06:24:57
Django version 3.0.2, using settings 'mysite.settings'
Starting development server at http://0:8000/
Quit the server with CONTROL-C.
Watching for file changes with StatReloader
Watching for file changes with StatReloader
Exception in thread django-main-thread:
Traceback (most recent call last):
  File "/usr/lib/python3.6/threading.py", line 916, in _bootstrap_inner
    self.run()
  File "/usr/lib/python3.6/threading.py", line 864, in run
    self._target(*self._args, **self._kwargs)
  File "/usr/local/lib/python3.6/dist-packages/django/utils/autoreload.py", line 53, in wrapper
    fn(*args, **kwargs)
  File "/usr/local/lib/python3.6/dist-packages/django/core/management/commands/runserver.py", line 117, in inner_run
    self.check(display_num_errors=True)
  File "/usr/local/lib/python3.6/dist-packages/django/core/management/base.py", line 395, in check
    include_deployment_checks=include_deployment_checks,
  File "/usr/local/lib/python3.6/dist-packages/django/core/management/base.py", line 382, in _run_checks
    return checks.run_checks(**kwargs)
  File "/usr/local/lib/python3.6/dist-packages/django/core/checks/registry.py", line 72, in run_checks
    new_errors = check(app_configs=app_configs)
  File "/usr/local/lib/python3.6/dist-packages/django/core/checks/urls.py", line 13, in check_url_config
    return check_resolver(resolver)
  File "/usr/local/lib/python3.6/dist-packages/django/core/checks/urls.py", line 23, in check_resolver
    return check_method()
  File "/usr/local/lib/python3.6/dist-packages/django/urls/resolvers.py", line 407, in check
    for pattern in self.url_patterns:
  File "/usr/local/lib/python3.6/dist-packages/django/utils/functional.py", line 48, in __get__
    res = instance.__dict__[self.name] = self.func(instance)
  File "/usr/local/lib/python3.6/dist-packages/django/urls/resolvers.py", line 588, in url_patterns
    patterns = getattr(self.urlconf_module, "urlpatterns", self.urlconf_module)
  File "/usr/local/lib/python3.6/dist-packages/django/utils/functional.py", line 48, in __get__
    res = instance.__dict__[self.name] = self.func(instance)
  File "/usr/local/lib/python3.6/dist-packages/django/urls/resolvers.py", line 581, in urlconf_module
    return import_module(self.urlconf_name)
  File "/usr/lib/python3.6/importlib/__init__.py", line 126, in import_module
    return _bootstrap._gcd_import(name[level:], package, level)
  File "<frozen importlib._bootstrap>", line 994, in _gcd_import
  File "<frozen importlib._bootstrap>", line 971, in _find_and_load
  File "<frozen importlib._bootstrap>", line 955, in _find_and_load_unlocked
  File "<frozen importlib._bootstrap>", line 665, in _load_unlocked
  File "<frozen importlib._bootstrap_external>", line 678, in exec_module
  File "<frozen importlib._bootstrap>", line 219, in _call_with_frames_removed
  File "/home/ubuntu/ece568/erss-hwk1-bh214/docker-deploy/web-app/mysite/urls.py", line 21, in <module>
    path('uper/', include('uper.urls')),
  File "/usr/local/lib/python3.6/dist-packages/django/urls/conf.py", line 34, in include
    urlconf_module = import_module(urlconf_module)
  File "/usr/lib/python3.6/importlib/__init__.py", line 126, in import_module
    return _bootstrap._gcd_import(name[level:], package, level)
  File "<frozen importlib._bootstrap>", line 994, in _gcd_import
  File "<frozen importlib._bootstrap>", line 971, in _find_and_load
  File "<frozen importlib._bootstrap>", line 955, in _find_and_load_unlocked
  File "<frozen importlib._bootstrap>", line 665, in _load_unlocked
  File "<frozen importlib._bootstrap_external>", line 678, in exec_module
  File "<frozen importlib._bootstrap>", line 219, in _call_with_frames_removed
  File "/home/ubuntu/ece568/erss-hwk1-bh214/docker-deploy/web-app/uper/urls.py", line 3, in <module>
    from . import views
  File "/home/ubuntu/ece568/erss-hwk1-bh214/docker-deploy/web-app/uper/views.py", line 30
    send_mail(
            ^
IndentationError: expected an indented block

/home/ubuntu/ece568/erss-hwk1-bh214/docker-deploy/web-app/uper/views.py changed, reloading.
Performing system checks...

Exception in thread django-main-thread:
Traceback (most recent call last):
  File "/usr/lib/python3.6/threading.py", line 916, in _bootstrap_inner
    self.run()
  File "/usr/lib/python3.6/threading.py", line 864, in run
    self._target(*self._args, **self._kwargs)
  File "/usr/local/lib/python3.6/dist-packages/django/utils/autoreload.py", line 53, in wrapper
    fn(*args, **kwargs)
  File "/usr/local/lib/python3.6/dist-packages/django/core/management/commands/runserver.py", line 117, in inner_run
    self.check(display_num_errors=True)
  File "/usr/local/lib/python3.6/dist-packages/django/core/management/base.py", line 395, in check
    include_deployment_checks=include_deployment_checks,
  File "/usr/local/lib/python3.6/dist-packages/django/core/management/base.py", line 382, in _run_checks
    return checks.run_checks(**kwargs)
  File "/usr/local/lib/python3.6/dist-packages/django/core/checks/registry.py", line 72, in run_checks
    new_errors = check(app_configs=app_configs)
  File "/usr/local/lib/python3.6/dist-packages/django/core/checks/urls.py", line 13, in check_url_config
    return check_resolver(resolver)
  File "/usr/local/lib/python3.6/dist-packages/django/core/checks/urls.py", line 23, in check_resolver
    return check_method()
  File "/usr/local/lib/python3.6/dist-packages/django/urls/resolvers.py", line 407, in check
    for pattern in self.url_patterns:
  File "/usr/local/lib/python3.6/dist-packages/django/utils/functional.py", line 48, in __get__
    res = instance.__dict__[self.name] = self.func(instance)
  File "/usr/local/lib/python3.6/dist-packages/django/urls/resolvers.py", line 588, in url_patterns
    patterns = getattr(self.urlconf_module, "urlpatterns", self.urlconf_module)
  File "/usr/local/lib/python3.6/dist-packages/django/utils/functional.py", line 48, in __get__
    res = instance.__dict__[self.name] = self.func(instance)
  File "/usr/local/lib/python3.6/dist-packages/django/urls/resolvers.py", line 581, in urlconf_module
    return import_module(self.urlconf_name)
  File "/usr/lib/python3.6/importlib/__init__.py", line 126, in import_module
    return _bootstrap._gcd_import(name[level:], package, level)
  File "<frozen importlib._bootstrap>", line 994, in _gcd_import
  File "<frozen importlib._bootstrap>", line 971, in _find_and_load
  File "<frozen importlib._bootstrap>", line 955, in _find_and_load_unlocked
  File "<frozen importlib._bootstrap>", line 665, in _load_unlocked
  File "<frozen importlib._bootstrap_external>", line 678, in exec_module
  File "<frozen importlib._bootstrap>", line 219, in _call_with_frames_removed
  File "/home/ubuntu/ece568/erss-hwk1-bh214/docker-deploy/web-app/mysite/urls.py", line 21, in <module>
    path('uper/', include('uper.urls')),
  File "/usr/local/lib/python3.6/dist-packages/django/urls/conf.py", line 34, in include
    urlconf_module = import_module(urlconf_module)
  File "/usr/lib/python3.6/importlib/__init__.py", line 126, in import_module
    return _bootstrap._gcd_import(name[level:], package, level)
  File "<frozen importlib._bootstrap>", line 994, in _gcd_import
  File "<frozen importlib._bootstrap>", line 971, in _find_and_load
  File "<frozen importlib._bootstrap>", line 955, in _find_and_load_unlocked
  File "<frozen importlib._bootstrap>", line 665, in _load_unlocked
  File "<frozen importlib._bootstrap_external>", line 678, in exec_module
  File "<frozen importlib._bootstrap>", line 219, in _call_with_frames_removed
  File "/home/ubuntu/ece568/erss-hwk1-bh214/docker-deploy/web-app/uper/urls.py", line 3, in <module>
    from . import views
  File "/home/ubuntu/ece568/erss-hwk1-bh214/docker-deploy/web-app/uper/views.py", line 30
    send_mail(
            ^
IndentationError: expected an indented block

/home/ubuntu/ece568/erss-hwk1-bh214/docker-deploy/web-app/uper/views.py changed, reloading.
Performing system checks...

Watching for file changes with StatReloader
Watching for file changes with StatReloader
Internal Server Error: /uper/main_page/
Traceback (most recent call last):
  File "/usr/local/lib/python3.6/dist-packages/django/core/handlers/exception.py", line 34, in inner
    response = get_response(request)
  File "/usr/local/lib/python3.6/dist-packages/django/core/handlers/base.py", line 115, in _get_response
    response = self.process_exception_by_middleware(e, request)
  File "/usr/local/lib/python3.6/dist-packages/django/core/handlers/base.py", line 113, in _get_response
    response = wrapped_callback(request, *callback_args, **callback_kwargs)
  File "/home/ubuntu/ece568/erss-hwk1-bh214/docker-deploy/web-app/uper/views.py", line 35, in main_page
    fail_silently=False,
  File "/usr/local/lib/python3.6/dist-packages/django/core/mail/__init__.py", line 60, in send_mail
    return mail.send()
  File "/usr/local/lib/python3.6/dist-packages/django/core/mail/message.py", line 276, in send
    return self.get_connection(fail_silently).send_messages([self])
  File "/usr/local/lib/python3.6/dist-packages/django/core/mail/backends/smtp.py", line 102, in send_messages
    new_conn_created = self.open()
  File "/usr/local/lib/python3.6/dist-packages/django/core/mail/backends/smtp.py", line 69, in open
    self.connection.login(self.username, self.password)
  File "/usr/lib/python3.6/smtplib.py", line 697, in login
    "SMTP AUTH extension not supported by server.")
smtplib.SMTPNotSupportedError: SMTP AUTH extension not supported by server.
[07/Feb/2020 06:25:16] "GET /uper/main_page/ HTTP/1.1" 500 86320
/home/ubuntu/ece568/erss-hwk1-bh214/docker-deploy/web-app/mysite/settings.py changed, reloading.
Performing system checks...

System check identified no issues (0 silenced).
February 07, 2020 - 06:25:04
Django version 3.0.2, using settings 'mysite.settings'
Starting development server at http://0:8080/
Quit the server with CONTROL-C.
/home/ubuntu/ece568/erss-hwk1-bh214/docker-deploy/web-app/mysite/settings.py changed, reloading.
Performing system checks...

System check identified no issues (0 silenced).
February 07, 2020 - 06:25:04
Django version 3.0.2, using settings 'mysite.settings'
Starting development server at http://0:8000/
Quit the server with CONTROL-C.
Traceback (most recent call last):
  File "manage.py", line 21, in <module>
    main()
  File "manage.py", line 17, in main
    execute_from_command_line(sys.argv)
  File "/usr/local/lib/python3.6/dist-packages/django/core/management/__init__.py", line 401, in execute_from_command_line
    utility.execute()
  File "/usr/local/lib/python3.6/dist-packages/django/core/management/__init__.py", line 345, in execute
    settings.INSTALLED_APPS
  File "/usr/local/lib/python3.6/dist-packages/django/conf/__init__.py", line 76, in __getattr__
    self._setup(name)
  File "/usr/local/lib/python3.6/dist-packages/django/conf/__init__.py", line 63, in _setup
    self._wrapped = Settings(settings_module)
  File "/usr/local/lib/python3.6/dist-packages/django/conf/__init__.py", line 142, in __init__
    mod = importlib.import_module(self.SETTINGS_MODULE)
  File "/usr/lib/python3.6/importlib/__init__.py", line 126, in import_module
    return _bootstrap._gcd_import(name[level:], package, level)
  File "<frozen importlib._bootstrap>", line 994, in _gcd_import
  File "<frozen importlib._bootstrap>", line 971, in _find_and_load
  File "<frozen importlib._bootstrap>", line 955, in _find_and_load_unlocked
  File "<frozen importlib._bootstrap>", line 665, in _load_unlocked
  File "<frozen importlib._bootstrap_external>", line 678, in exec_module
  File "<frozen importlib._bootstrap>", line 219, in _call_with_frames_removed
  File "/home/ubuntu/ece568/erss-hwk1-bh214/docker-deploy/web-app/mysite/settings.py", line 35, in <module>
    EMAIL_USE_TLS
NameError: name 'EMAIL_USE_TLS' is not defined
Traceback (most recent call last):
  File "manage.py", line 21, in <module>
    main()
  File "manage.py", line 17, in main
    execute_from_command_line(sys.argv)
  File "/usr/local/lib/python3.6/dist-packages/django/core/management/__init__.py", line 401, in execute_from_command_line
    utility.execute()
  File "/usr/local/lib/python3.6/dist-packages/django/core/management/__init__.py", line 345, in execute
    settings.INSTALLED_APPS
  File "/usr/local/lib/python3.6/dist-packages/django/conf/__init__.py", line 76, in __getattr__
    self._setup(name)
  File "/usr/local/lib/python3.6/dist-packages/django/conf/__init__.py", line 63, in _setup
    self._wrapped = Settings(settings_module)
  File "/usr/local/lib/python3.6/dist-packages/django/conf/__init__.py", line 142, in __init__
    mod = importlib.import_module(self.SETTINGS_MODULE)
  File "/usr/lib/python3.6/importlib/__init__.py", line 126, in import_module
    return _bootstrap._gcd_import(name[level:], package, level)
  File "<frozen importlib._bootstrap>", line 994, in _gcd_import
  File "<frozen importlib._bootstrap>", line 971, in _find_and_load
  File "<frozen importlib._bootstrap>", line 955, in _find_and_load_unlocked
  File "<frozen importlib._bootstrap>", line 665, in _load_unlocked
  File "<frozen importlib._bootstrap_external>", line 678, in exec_module
  File "<frozen importlib._bootstrap>", line 219, in _call_with_frames_removed
  File "/home/ubuntu/ece568/erss-hwk1-bh214/docker-deploy/web-app/mysite/settings.py", line 35, in <module>
    EMAIL_USE_TLS
NameError: name 'EMAIL_USE_TLS' is not defined
